Workbook

Sheet MENU
B2: THÔNG TIN LỚP HỌC | I2: THỐNG KÊ LỚP HỌC
C3: Tên nghề đào tạo | E3: Nuôi và phòng trị bệnh cho trâu, bò | I3: Nội dung thống kê | K3: Nhập học | L3: Tốt nghiệp
C4: Khóa | E4: 1 | I4: Tổng số học viên | K4: =SUM(K5:K9) | L4: =COUNTIF('Thông tin hoc sinh'!P3:P37,"x")
C5: Năm đào tạo | E5: 2018 | I5: Nhóm đối tượng | J5: 1 | K5: =COUNTIF('Thông tin hoc sinh'!$J$3:$J$37,J5) | L5: =COUNTIF('Thông tin hoc sinh'!$AG$3:$AG$37,J5)
C6: Địa điểm đào tạo | D6: Xã: | E6: Ngọk Tụ | J6: 2 | K6: =COUNTIF('Thông tin hoc sinh'!$J$3:$J$37,J6) | L6: =COUNTIF('Thông tin hoc sinh'!$AG$3:$AG$37,J6)
D7: Huyện: | E7: =VLOOKUP(E6,IDs!$H$4:$I$46,2,0) | J7: 3 | K7: =COUNTIF('Thông tin hoc sinh'!$J$3:$J$37,J7) | L7: =COUNTIF('Thông tin hoc sinh'!$AG$3:$AG$37,J7)
C8: Là nghề | E8: =VLOOKUP(E3,IDs!$B$4:$C$33,2,1) | J8: 4 | K8: =COUNTIF('Thông tin hoc sinh'!$J$3:$J$37,J8) | L8: =COUNTIF('Thông tin hoc sinh'!$AG$3:$AG$37,J8)
J9: 5 | K9: =COUNTIF('Thông tin hoc sinh'!$J$3:$J$37,J9) | L9: =COUNTIF('Thông tin hoc sinh'!$AG$3:$AG$37,J9)
I10: Nữ | K10: =COUNTIF('Thông tin hoc sinh'!$D$3:$D$37,"Nữ") | L10: ='Thông tin hoc sinh'!AH38
B11: CÔNG CỤ TẠO HỒ SƠ LỚP ĐÀO TẠO NGHỀ | I11: Dân tộc thiểu số | K11: ='Thông tin hoc sinh'!R38 | L11: ='Thông tin hoc sinh'!AJ38
B12: 1 | C12: Quyết định mở lớp | I12: Nữ dân tộc thiểu số | K12: ='Thông tin hoc sinh'!Q38 | L12: ='Thông tin hoc sinh'!AI38
B13: 2 | C13: Quyết định điều động | I13: Thanh niên | K13: ='Thông tin hoc sinh'!S38 | L13: ='Thông tin hoc sinh'!AK38
B14: 3 | C14: Quyết định thành lập BQL lớp | I14: Thanh niên DTTS | K14: ='Thông tin hoc sinh'!T38 | L14: ='Thông tin hoc sinh'!AL38
B15: 4 | C15: Quyết định thành lập Hội đồng KT KTKH | I15: Tốt nghiệp THCS | J15: Tổng | K15: ='Thông tin hoc sinh'!U38 | L15: ='Thông tin hoc sinh'!AM38
B16: 5 | C16: Biên bản họp Hội đồng lần 1 | J16: Nữ | K16: ='Thông tin hoc sinh'!V38 | L16: ='Thông tin hoc sinh'!AN38
B17: 6 | C17: Bản phân công | J17: DTTS | K17: ='Thông tin hoc sinh'!W38 | L17: ='Thông tin hoc sinh'!AO38
B18: 7 | C18: Biên bản họp Hội đồng Thi lại | I18: Từ 25 tuổi trở xuống | J18: Tổng | K18: ='Thông tin hoc sinh'!X38 | L18: ='Thông tin hoc sinh'!AP38
B19: 8 | C19: Biên bản họp Hội đồng lần 2 | J19: Nữ | K19: ='Thông tin hoc sinh'!Y38 | L19: ='Thông tin hoc sinh'!AQ38
B20: 9 | C20: Quyết định công nhận tốt nghiệp | J20: DTTS | K20: ='Thông tin hoc sinh'!Z38 | L20: ='Thông tin hoc sinh'!AR38
B21: 10 | C21: Quyết định khen thưởng | I21: Từ 26 - 45 tuổi | J21: Tổng | K21: ='Thông tin hoc sinh'!AA38 | L21: ='Thông tin hoc sinh'!AS38
J22: Nữ | K22: ='Thông tin hoc sinh'!AB38 | L22: ='Thông tin hoc sinh'!AT38
C23: XẾP LOẠI TỐT NGHIỆP | J23: DTTS | K23: ='Thông tin hoc sinh'!AC38 | L23: ='Thông tin hoc sinh'!AU38
C24: ='Công nhận tốt nghiệp'!J9 | D24: ='Công nhận tốt nghiệp'!K9 | E24: ='Công nhận tốt nghiệp'!L9 | I24: Từ 46 tuổi trở lên | J24: Tổng | K24: ='Thông tin hoc sinh'!AD38 | L24: ='Thông tin hoc sinh'!AV38
C25: ='Công nhận tốt nghiệp'!J10 | D25: ='Công nhận tốt nghiệp'!K10 | E25: ='Công nhận tốt nghiệp'!L10 | J25: Nữ | K25: ='Thông tin hoc sinh'!AE38 | L25: ='Thông tin hoc sinh'!AW38
C26: ='Công nhận tốt nghiệp'!J11 | D26: ='Công nhận tốt nghiệp'!K11 | E26: ='Công nhận tốt nghiệp'!L11 | J26: DTTS | K26: ='Thông tin hoc sinh'!AF38 | L26: ='Thông tin hoc sinh'!AX38
C27: ='Công nhận tốt nghiệp'!J12 | D27: ='Công nhận tốt nghiệp'!K12 | E27: ='Công nhận tốt nghiệp'!L12
C28: ='Công nhận tốt nghiệp'!J13 | D28: ='Công nhận tốt nghiệp'!K13 | E28: ='Công nhận tốt nghiệp'!L13
C29: ='Công nhận tốt nghiệp'!J14 | D29: ='Công nhận tốt nghiệp'!K14 | E29: ='Công nhận tốt nghiệp'!L14

Sheet Thông tin hoc sinh
A1: Số TT | B1: Họ và tên | C1: Ngày, tháng, năm sinh | D1: Giới tính | E1: Dân tộc | F1: Thanh niên | G1: Thanh niên DTTS | H1: Trình độ văn hóa | I1: Nhóm đối tượng | K1: Nơi sinh | L1: Nguyên quán | M1: Nơi cư trú | N1: Kiểm tra tuổi | O1: Yêu cầu về hồ sơ | P1: Tốt nghiệp | Q1: Nữ DTTS | R1: DTTS | S1: Thanh niên | T1: Thanh niên DTTS | U1: Tốt nghiệp THCS | X1: Từ 25 tuổi trở xuống | AA1: Từ 26, 45 tuổi | AD1: Từ 46 tuổi trở lên | AG1: Nhóm đối tượng | AH1: Nữ | AI1: Nữ DTTS | AJ1: DTTS | AK1: Thanh niên | AL1: Thanh niên DTTS | AM1: Tốt nghiệp THCS | AP1: Từ 25 tuổi trở xuống | AS1: Từ 26, 45 tuổi | AV1: Từ 46 tuổi trở lên
I2: Tên đối tượng | J2: Thuộc nhóm | U2: Tổng | V2: Nữ | W2: DTTS | X2: Tổng | Y2: Nữ | Z2: DTTS | AA2: Tổng | AB2: Nữ | AC2: DTTS | AD2: Tổng | AE2: Nữ | AF2: DTTS | AM2: Tổng | AN2: Nữ | AO2: DTTS | AP2: Tổng | AQ2: Nữ | AR2: DTTS | AS2: Tổng | AT2: Nữ | AU2: DTTS | AV2: Tổng | AW2: Nữ | AX2: DTTS
A3: 01 | B3: Y Hương | C3: 1986 | D3: Nữ | E3: Xê Đăng | F3: =IF(YEAR(TODAY())-C3<=30,"X","") | G3: =IF(AND(F3="X",E3<>"Kinh"),"X","") | H3: 6 | I3: Người dân tộc thiểu số | J3: =VLOOKUP(I3,IDs!$B$37:$C$46,2,0) | K3: Kon Đào, ĐăkTô, Kon Tum | L3: Đăk Tô, Kon Tum | M3: Đăk Nu, Ngọk Tụ, Đăk Tô, Kon Tum | N3: =IF(C3="","",IF(YEAR(TODAY())-C3<15,"Không đủ tuổi theo học",IF(AND(D3="Nam",YEAR(TODAY())-C3>60),"Quá tuổi theo học",IF(AND(D3="Nữ",YEAR(TODAY())-C3>55),"Quá tuổi theo học","Đảm bảo")))) | O3: =IF(B3="","",IF(OR(LEFT(B3,1)="Y",LEFT(B3,1)="A"),"",IF(I3<>"Đối tượng lao động nông thôn khác","Cần hồ sơ chứng minh nhóm đối tượng",""))) | P3: x | Q3: =IF(B3<>"",AND(D3="Nữ",I3="Người dân tộc thiểu số"),"") | R3: =IF(B3<>"",I3="Người dân tộc thiểu số","") | S3: =IF(B3<>"",MENU!$E$5-'Thông tin hoc sinh'!C3<31,"") | T3: =IF(B3<>"",AND(R3,S3),"") | U3: =IF(B3<>"",(H3>=9),"") | V3: =IF(B3<>"",AND(U3,D3="Nữ"),"") | W3: =IF(B3<>"",AND(U3,R3),"") | X3: =IF(B3<>"",MENU!$E$5-'Thông tin hoc sinh'!C3<26,"") | Y3: =IF(B3<>"",AND(X3,D3="Nữ"),"") | Z3: =IF(B3<>"",AND(X3,R3),"") | AA3: =IF(B3<>"",AND(MENU!$E$5-'Thông tin hoc sinh'!C3>=26,MENU!$E$5-'Thông tin hoc sinh'!C3<=45),"") | AB3: =IF(B3<>"",AND(AA3,D3="Nữ"),"") | AC3: =IF(B3<>"",AND(AA3,R3),"") | AD3: =IF(B3<>"",MENU!$E$5-'Thông tin hoc sinh'!C3>45,"") | AE3: =IF(B3<>"",AND(AD3,D3="Nữ"),"") | AF3: =IF(B3<>"",AND(AD3,R3),"") | AG3: =IF(P3<>"",J3,"") | AH3: =IF(B3<>"",AND(P3="x",D3="Nữ"),"") | AI3: =IF(B3<>"",AND(P3="x",D3="Nữ",I3="Người dân tộc thiểu số"),"") | AJ3: =IF(B3<>"",AND(P3="x",I3="Người dân tộc thiểu số"),"") | AK3: =IF(B3<>"",AND(P3="x",MENU!$E$5-'Thông tin hoc sinh'!C3<31),"") | AL3: =IF(B3<>"",AND(P3="x",R3,S3),"") | AM3: =IF(B3<>"",AND(H3>=9,P3="x"),"") | AN3: =IF(B3<>"",AND(P3="x",X3,D3="Nữ"),"") | AO3: =IF(B3<>"",AND(P3="x",U3,R3),"") | AP3: =IF(B3<>"",AND(P3="x",MENU!$E$5-'Thông tin hoc sinh'!C3<26),"") | AQ3: =IF(B3<>"",AND(P3="x",X3,D3="Nữ"),"") | AR3: =IF(B3<>"",AND(P3="x",X3,R3),"") | AS3: =IF(B3<>"",AND(P3="x",MENU!$E$5-'Thông tin hoc sinh'!C3>=26,MENU!$E$5-'Thông tin hoc sinh'!C3<=45),"") | AT3: =IF(B3<>"",AND(P3="x",AA3,D3="Nữ"),"") | AU3: =IF(B3<>"",AND(P3="x",AA3,R3),"") | AV3: =IF(B3<>"",AND(P3="x",MENU!$E$5-'Thông tin hoc sinh'!C3>45),"") | AW3: =IF(B3<>"",AND(P3="x",AD3,D3="Nữ"),"") | AX3: =IF(B3<>"",AND(P3="x",AD3,R3),"")
A4: 02 | B4: Y Điêr | C4: 1993 | D4: Nữ | E4: Xê Đăng | F4: =IF(YEAR(TODAY())-C4<=30,"X","") | G4: =IF(AND(F4="X",E4<>"Kinh"),"X","") | H4: 12 | I4: Người dân tộc thiểu số | J4: =VLOOKUP(I4,IDs!$B$37:$C$46,2,0) | K4: Kon Đào, ĐăkTô, Kon Tum | L4: Đăk Tô, Kon Tum | M4: Đăk Nu, Ngọk Tụ, Đăk Tô, Kon Tum | N4: =IF(C4="","",IF(YEAR(TODAY())-C4<15,"Không đủ tuổi theo học",IF(AND(D4="Nam",YEAR(TODAY())-C4>60),"Quá tuổi theo học",IF(AND(D4="Nữ",YEAR(TODAY())-C4>55),"Quá tuổi theo học","Đảm bảo")))) | O4: =IF(B4="","",IF(OR(LEFT(B4,1)="Y",LEFT(B4,1)="A"),"",IF(I4<>"Đối tượng lao động nông thôn khác","Cần hồ sơ chứng minh nhóm đối tượng",""))) | P4: x | Q4: =IF(B4<>"",AND(D4="Nữ",I4="Người dân tộc thiểu số"),"") | R4: =IF(B4<>"",I4="Người dân tộc thiểu số","") | S4: =IF(B4<>"",MENU!$E$5-'Thông tin hoc sinh'!C4<31,"") | T4: =IF(B4<>"",AND(R4,S4),"") | U4: =IF(B4<>"",(H4>=9),"") | V4: =IF(B4<>"",AND(U4,D4="Nữ"),"") | W4: =IF(B4<>"",AND(U4,R4),"") | X4: =IF(B4<>"",MENU!$E$5-'Thông tin hoc sinh'!C4<26,"") | Y4: =IF(B4<>"",AND(X4,D4="Nữ"),"") | Z4: =IF(B4<>"",AND(X4,R4),"") | AA4: =IF(B4<>"",AND(MENU!$E$5-'Thông tin hoc sinh'!C4>=26,MENU!$E$5-'Thông tin hoc sinh'!C4<=45),"") | AB4: =IF(B4<>"",AND(AA4,D4="Nữ"),"") | AC4: =IF(B4<>"",AND(AA4,R4),"") | AD4: =IF(B4<>"",MENU!$E$5-'Thông tin hoc sinh'!C4>45,"") | AE4: =IF(B4<>"",AND(AD4,D4="Nữ"),"") | AF4: =IF(B4<>"",AND(AD4,R4),"") | AG4: =IF(P4<>"",J4,"") | AH4: =IF(B4<>"",AND(P4="x",D4="Nữ"),"") | AI4: =IF(B4<>"",AND(P4="x",D4="Nữ",I4="Người dân tộc thiểu số"),"") | AJ4: =IF(B4<>"",AND(P4="x",I4="Người dân tộc thiểu số"),"") | AK4: =IF(B4<>"",AND(P4="x",MENU!$E$5-'Thông tin hoc sinh'!C4<31),"") | AL4: =IF(B4<>"",AND(P4="x",R4,S4),"") | AM4: =IF(B4<>"",AND(H4>=9,P4="x"),"") | AN4: =IF(B4<>"",AND(P4="x",X4,D4="Nữ"),"") | AO4: =IF(B4<>"",AND(P4="x",U4,R4),"") | AP4: =IF(B4<>"",AND(P4="x",MENU!$E$5-'Thông tin hoc sinh'!C4<26),"") | AQ4: =IF(B4<>"",AND(P4="x",X4,D4="Nữ"),"") | AR4: =IF(B4<>"",AND(P4="x",X4,R4),"") | AS4: =IF(B4<>"",AND(P4="x",MENU!$E$5-'Thông tin hoc sinh'!C4>=26,MENU!$E$5-'Thông tin hoc sinh'!C4<=45),"") | AT4: =IF(B4<>"",AND(P4="x",AA4,D4="Nữ"),"") | AU4: =IF(B4<>"",AND(P4="x",AA4,R4),"") | AV4: =IF(B4<>"",AND(P4="x",MENU!$E$5-'Thông tin hoc sinh'!C4>45),"") | AW4: =IF(B4<>"",AND(P4="x",AD4,D4="Nữ"),"") | AX4: =IF(B4<>"",AND(P4="x",AD4,R4),"")
A5: 03 | B5: Y Hdiết | C5: 1995 | D5: Nữ | E5: Xê Đăng | F5: =IF(YEAR(TODAY())-C5<=30,"X","") | G5: =IF(AND(F5="X",E5<>"Kinh"),"X","") | H5: 11 | I5: Người dân tộc thiểu số | J5: =VLOOKUP(I5,IDs!$B$37:$C$46,2,0) | K5: Kon Đào, ĐăkTô, Kon Tum | L5: Đăk Tô, Kon Tum | M5: Đăk Nu, Ngọk Tụ, Đăk Tô, Kon Tum | N5: =IF(C5="","",IF(YEAR(TODAY())-C5<15,"Không đủ tuổi theo học",IF(AND(D5="Nam",YEAR(TODAY())-C5>60),"Quá tuổi theo học",IF(AND(D5="Nữ",YEAR(TODAY())-C5>55),"Quá tuổi theo học","Đảm bảo")))) | O5: =IF(B5="","",IF(OR(LEFT(B5,1)="Y",LEFT(B5,1)="A"),"",IF(I5<>"Đối tượng lao động nông thôn khác","Cần hồ sơ chứng minh nhóm đối tượng",""))) | P5: x | Q5: =IF(B5<>"",AND(D5="Nữ",I5="Người dân tộc thiểu số"),"") | R5: =IF(B5<>"",I5="Người dân tộc thiểu số","") | S5: =IF(B5<>"",MENU!$E$5-'Thông tin hoc sinh'!C5<31,"") | T5: =IF(B5<>"",AND(R5,S5),"") | U5: =IF(B5<>"",(H5>=9),"") | V5: =IF(B5<>"",AND(U5,D5="Nữ"),"") | W5: =IF(B5<>"",AND(U5,R5),"") | X5: =IF(B5<>"",MENU!$E$5-'Thông tin hoc sinh'!C5<26,"") | Y5: =IF(B5<>"",AND(X5,D5="Nữ"),"") | Z5: =IF(B5<>"",AND(X5,R5),"") | AA5: =IF(B5<>"",AND(MENU!$E$5-'Thông tin hoc sinh'!C5>=26,MENU!$E$5-'Thông tin hoc sinh'!C5<=45),"") | AB5: =IF(B5<>"",AND(AA5,D5="Nữ"),"") | AC5: =IF(B5<>"",AND(AA5,R5),"") | AD5: =IF(B5<>"",MENU!$E$5-'Thông tin hoc sinh'!C5>45,"") | AE5: =IF(B5<>"",AND(AD5,D5="Nữ"),"") | AF5: =IF(B5<>"",AND(AD5,R5),"") | AG5: =IF(P5<>"",J5,"") | AH5: =IF(B5<>"",AND(P5="x",D5="Nữ"),"") | AI5: =IF(B5<>"",AND(P5="x",D5="Nữ",I5="Người dân tộc thiểu số"),"") | AJ5: =IF(B5<>"",AND(P5="x",I5="Người dân tộc thiểu số"),"") | AK5: =IF(B5<>"",AND(P5="x",MENU!$E$5-'Thông tin hoc sinh'!C5<31),"") | AL5: =IF(B5<>"",AND(P5="x",R5,S5),"") | AM5: =IF(B5<>"",AND(H5>=9,P5="x"),"") | AN5: =IF(B5<>"",AND(P5="x",X5,D5="Nữ"),"") | AO5: =IF(B5<>"",AND(P5="x",U5,R5),"") | AP5: =IF(B5<>"",AND(P5="x",MENU!$E$5-'Thông tin hoc sinh'!C5<26),"") | AQ5: =IF(B5<>"",AND(P5="x",X5,D5="Nữ"),"") | AR5: =IF(B5<>"",AND(P5="x",X5,R5),"") | AS5: =IF(B5<>"",AND(P5="x",MENU!$E$5-'Thông tin hoc sinh'!C5>=26,MENU!$E$5-'Thông tin hoc sinh'!C5<=45),"") | AT5: =IF(B5<>"",AND(P5="x",AA5,D5="Nữ"),"") | AU5: =IF(B5<>"",AND(P5="x",AA5,R5),"") | AV5: =IF(B5<>"",AND(P5="x",MENU!$E$5-'Thông tin hoc sinh'!C5>45),"") | AW5: =IF(B5<>"",AND(P5="x",AD5,D5="Nữ"),"") | AX5: =IF(B5<>"",AND(P5="x",AD5,R5),"")
A6: 04 | B6: Y Sương | C6: 1981 | D6: Nữ | E6: Xê Đăng | F6: =IF(YEAR(TODAY())-C6<=30,"X","") | G6: =IF(AND(F6="X",E6<>"Kinh"),"X","") | H6: 9 | I6: Người dân tộc thiểu số | J6: =VLOOKUP(I6,IDs!$B$37:$C$46,2,0) | K6: Kon Đào, ĐăkTô, Kon Tum | L6: Đăk Tô, Kon Tum | M6: Đăk Nu, Ngọk Tụ, Đăk Tô, Kon Tum | N6: =IF(C6="","",IF(YEAR(TODAY())-C6<15,"Không đủ tuổi theo học",IF(AND(D6="Nam",YEAR(TODAY())-C6>60),"Quá tuổi theo học",IF(AND(D6="Nữ",YEAR(TODAY())-C6>55),"Quá tuổi theo học","Đảm bảo")))) | O6: =IF(B6="","",IF(OR(LEFT(B6,1)="Y",LEFT(B6,1)="A"),"",IF(I6<>"Đối tượng lao động nông thôn khác","Cần hồ sơ chứng minh nhóm đối tượng",""))) | P6: x | Q6: =IF(B6<>"",AND(D6="Nữ",I6="Người dân tộc thiểu số"),"") | R6: =IF(B6<>"",I6="Người dân tộc thiểu số","") | S6: =IF(B6<>"",MENU!$E$5-'Thông tin hoc sinh'!C6<31,"") | T6: =IF(B6<>"",AND(R6,S6),"") | U6: =IF(B6<>"",(H6>=9),"") | V6: =IF(B6<>"",AND(U6,D6="Nữ"),"") | W6: =IF(B6<>"",AND(U6,R6),"") | X6: =IF(B6<>"",MENU!$E$5-'Thông tin hoc sinh'!C6<26,"") | Y6: =IF(B6<>"",AND(X6,D6="Nữ"),"") | Z6: =IF(B6<>"",AND(X6,R6),"") | AA6: =IF(B6<>"",AND(MENU!$E$5-'Thông tin hoc sinh'!C6>=26,MENU!$E$5-'Thông tin hoc sinh'!C6<=45),"") | AB6: =IF(B6<>"",AND(AA6,D6="Nữ"),"") | AC6: =IF(B6<>"",AND(AA6,R6),"") | AD6: =IF(B6<>"",MENU!$E$5-'Thông tin hoc sinh'!C6>45,"") | AE6: =IF(B6<>"",AND(AD6,D6="Nữ"),"") | AF6: =IF(B6<>"",AND(AD6,R6),"") | AG6: =IF(P6<>"",J6,"") | AH6: =IF(B6<>"",AND(P6="x",D6="Nữ"),"") | AI6: =IF(B6<>"",AND(P6="x",D6="Nữ",I6="Người dân tộc thiểu số"),"") | AJ6: =IF(B6<>"",AND(P6="x",I6="Người dân tộc thiểu số"),"") | AK6: =IF(B6<>"",AND(P6="x",MENU!$E$5-'Thông tin hoc sinh'!C6<31),"") | AL6: =IF(B6<>"",AND(P6="x",R6,S6),"") | AM6: =IF(B6<>"",AND(H6>=9,P6="x"),"") | AN6: =IF(B6<>"",AND(P6="x",X6,D6="Nữ"),"") | AO6: =IF(B6<>"",AND(P6="x",U6,R6),"") | AP6: =IF(B6<>"",AND(P6="x",MENU!$E$5-'Thông tin hoc sinh'!C6<26),"") | AQ6: =IF(B6<>"",AND(P6="x",X6,D6="Nữ"),"") | AR6: =IF(B6<>"",AND(P6="x",X6,R6),"") | AS6: =IF(B6<>"",AND(P6="x",MENU!$E$5-'Thông tin hoc sinh'!C6>=26,MENU!$E$5-'Thông tin hoc sinh'!C6<=45),"") | AT6: =IF(B6<>"",AND(P6="x",AA6,D6="Nữ"),"") | AU6: =IF(B6<>"",AND(P6="x",AA6,R6),"") | AV6: =IF(B6<>"",AND(P6="x",MENU!$E$5-'Thông tin hoc sinh'!C6>45),"") | AW6: =IF(B6<>"",AND(P6="x",AD6,D6="Nữ"),"") | AX6: =IF(B6<>"",AND(P6="x",AD6,R6),"")
A7: 05 | B7: Y Minh | C7: 1975 | D7: Nữ | E7: Xê Đăng | F7: =IF(YEAR(TODAY())-C7<=30,"X","") | G7: =IF(AND(F7="X",E7<>"Kinh"),"X","") | H7: 5 | I7: Người dân tộc thiểu số | J7: =VLOOKUP(I7,IDs!$B$37:$C$46,2,0) | K7: Kon Đào, ĐăkTô, Kon Tum | L7: Tu Mơ Rông, Kon Tum | M7: Đăk Nu, Ngọk Tụ, Đăk Tô, Kon Tum | N7: =IF(C7="","",IF(YEAR(TODAY())-C7<15,"Không đủ tuổi theo học",IF(AND(D7="Nam",YEAR(TODAY())-C7>60),"Quá tuổi theo học",IF(AND(D7="Nữ",YEAR(TODAY())-C7>55),"Quá tuổi theo học","Đảm bảo")))) | O7: =IF(B7="","",IF(OR(LEFT(B7,1)="Y",LEFT(B7,1)="A"),"",IF(I7<>"Đối tượng lao động nông thôn khác","Cần hồ sơ chứng minh nhóm đối tượng",""))) | P7: x | Q7: =IF(B7<>"",AND(D7="Nữ",I7="Người dân tộc thiểu số"),"") | R7: =IF(B7<>"",I7="Người dân tộc thiểu số","") | S7: =IF(B7<>"",MENU!$E$5-'Thông tin hoc sinh'!C7<31,"") | T7: =IF(B7<>"",AND(R7,S7),"") | U7: =IF(B7<>"",(H7>=9),"") | V7: =IF(B7<>"",AND(U7,D7="Nữ"),"") | W7: =IF(B7<>"",AND(U7,R7),"") | X7: =IF(B7<>"",MENU!$E$5-'Thông tin hoc sinh'!C7<26,"") | Y7: =IF(B7<>"",AND(X7,D7="Nữ"),"") | Z7: =IF(B7<>"",AND(X7,R7),"") | AA7: =IF(B7<>"",AND(MENU!$E$5-'Thông tin hoc sinh'!C7>=26,MENU!$E$5-'Thông tin hoc sinh'!C7<=45),"") | AB7: =IF(B7<>"",AND(AA7,D7="Nữ"),"") | AC7: =IF(B7<>"",AND(AA7,R7),"") | AD7: =IF(B7<>"",MENU!$E$5-'Thông tin hoc sinh'!C7>45,"") | AE7: =IF(B7<>"",AND(AD7,D7="Nữ"),"") | AF7: =IF(B7<>"",AND(AD7,R7),"") | AG7: =IF(P7<>"",J7,"") | AH7: =IF(B7<>"",AND(P7="x",D7="Nữ"),"") | AI7: =IF(B7<>"",AND(P7="x",D7="Nữ",I7="Người dân tộc thiểu số"),"") | AJ7: =IF(B7<>"",AND(P7="x",I7="Người dân tộc thiểu số"),"") | AK7: =IF(B7<>"",AND(P7="x",MENU!$E$5-'Thông tin hoc sinh'!C7<31),"") | AL7: =IF(B7<>"",AND(P7="x",R7,S7),"") | AM7: =IF(B7<>"",AND(H7>=9,P7="x"),"") | AN7: =IF(B7<>"",AND(P7="x",X7,D7="Nữ"),"") | AO7: =IF(B7<>"",AND(P7="x",U7,R7),"") | AP7: =IF(B7<>"",AND(P7="x",MENU!$E$5-'Thông tin hoc sinh'!C7<26),"") | AQ7: =IF(B7<>"",AND(P7="x",X7,D7="Nữ"),"") | AR7: =IF(B7<>"",AND(P7="x",X7,R7),"") | AS7: =IF(B7<>"",AND(P7="x",MENU!$E$5-'Thông tin hoc sinh'!C7>=26,MENU!$E$5-'Thông tin hoc sinh'!C7<=45),"") | AT7: =IF(B7<>"",AND(P7="x",AA7,D7="Nữ"),"") | AU7: =IF(B7<>"",AND(P7="x",AA7,R7),"") | AV7: =IF(B7<>"",AND(P7="x",MENU!$E$5-'Thông tin hoc sinh'!C7>45),"") | AW7: =IF(B7<>"",AND(P7="x",AD7,D7="Nữ"),"") | AX7: =IF(B7<>"",AND(P7="x",AD7,R7),"")
A8: 06 | B8: Y Dép | C8: 1956 | D8: Nữ | E8: Xê Đăng | F8: =IF(YEAR(TODAY())-C8<=30,"X","") | G8: =IF(AND(F8="X",E8<>"Kinh"),"X","") | H8: 2 | I8: Người dân tộc thiểu số | J8: =VLOOKUP(I8,IDs!$B$37:$C$46,2,0) | K8: Kon Đào, ĐăkTô, Kon Tum | L8: Đăk Tô, Kon Tum | M8: Đăk Nu, Ngọk Tụ, Đăk Tô, Kon Tum | N8: =IF(C8="","",IF(YEAR(TODAY())-C8<15,"Không đủ tuổi theo học",IF(AND(D8="Nam",YEAR(TODAY())-C8>60),"Quá tuổi theo học",IF(AND(D8="Nữ",YEAR(TODAY())-C8>55),"Quá tuổi theo học","Đảm bảo")))) | O8: =IF(B8="","",IF(OR(LEFT(B8,1)="Y",LEFT(B8,1)="A"),"",IF(I8<>"Đối tượng lao động nông thôn khác","Cần hồ sơ chứng minh nhóm đối tượng",""))) | P8: x | Q8: =IF(B8<>"",AND(D8="Nữ",I8="Người dân tộc thiểu số"),"") | R8: =IF(B8<>"",I8="Người dân tộc thiểu số","") | S8: =IF(B8<>"",MENU!$E$5-'Thông tin hoc sinh'!C8<31,"") | T8: =IF(B8<>"",AND(R8,S8),"") | U8: =IF(B8<>"",(H8>=9),"") | V8: =IF(B8<>"",AND(U8,D8="Nữ"),"") | W8: =IF(B8<>"",AND(U8,R8),"") | X8: =IF(B8<>"",MENU!$E$5-'Thông tin hoc sinh'!C8<26,"") | Y8: =IF(B8<>"",AND(X8,D8="Nữ"),"") | Z8: =IF(B8<>"",AND(X8,R8),"") | AA8: =IF(B8<>"",AND(MENU!$E$5-'Thông tin hoc sinh'!C8>=26,MENU!$E$5-'Thông tin hoc sinh'!C8<=45),"") | AB8: =IF(B8<>"",AND(AA8,D8="Nữ"),"") | AC8: =IF(B8<>"",AND(AA8,R8),"") | AD8: =IF(B8<>"",MENU!$E$5-'Thông tin hoc sinh'!C8>45,"") | AE8: =IF(B8<>"",AND(AD8,D8="Nữ"),"") | AF8: =IF(B8<>"",AND(AD8,R8),"") | AG8: =IF(P8<>"",J8,"") | AH8: =IF(B8<>"",AND(P8="x",D8="Nữ"),"") | AI8: =IF(B8<>"",AND(P8="x",D8="Nữ",I8="Người dân tộc thiểu số"),"") | AJ8: =IF(B8<>"",AND(P8="x",I8="Người dân tộc thiểu số"),"") | AK8: =IF(B8<>"",AND(P8="x",MENU!$E$5-'Thông tin hoc sinh'!C8<31),"") | AL8: =IF(B8<>"",AND(P8="x",R8,S8),"") | AM8: =IF(B8<>"",AND(H8>=9,P8="x"),"") | AN8: =IF(B8<>"",AND(P8="x",X8,D8="Nữ"),"") | AO8: =IF(B8<>"",AND(P8="x",U8,R8),"") | AP8: =IF(B8<>"",AND(P8="x",MENU!$E$5-'Thông tin hoc sinh'!C8<26),"") | AQ8: =IF(B8<>"",AND(P8="x",X8,D8="Nữ"),"") | AR8: =IF(B8<>"",AND(P8="x",X8,R8),"") | AS8: =IF(B8<>"",AND(P8="x",MENU!$E$5-'Thông tin hoc sinh'!C8>=26,MENU!$E$5-'Thông tin hoc sinh'!C8<=45),"") | AT8: =IF(B8<>"",AND(P8="x",AA8,D8="Nữ"),"") | AU8: =IF(B8<>"",AND(P8="x",AA8,R8),"") | AV8: =IF(B8<>"",AND(P8="x",MENU!$E$5-'Thông tin hoc sinh'!C8>45),"") | AW8: =IF(B8<>"",AND(P8="x",AD8,D8="Nữ"),"") | AX8: =IF(B8<>"",AND(P8="x",AD8,R8),"")
A9: 07 | B9: Y Nghê | C9: 1986 | D9: Nữ | E9: Xê Đăng | F9: =IF(YEAR(TODAY())-C9<=30,"X","") | G9: =IF(AND(F9="X",E9<>"Kinh"),"X","") | H9: 3 | I9: Người dân tộc thiểu số | J9: =VLOOKUP(I9,IDs!$B$37:$C$46,2,0) | K9: Kon Đào, ĐăkTô, Kon Tum | L9: Đăk Tô, Kon Tum | M9: Đăk Nu, Ngọk Tụ, Đăk Tô, Kon Tum | N9: =IF(C9="","",IF(YEAR(TODAY())-C9<15,"Không đủ tuổi theo học",IF(AND(D9="Nam",YEAR(TODAY())-C9>60),"Quá tuổi theo học",IF(AND(D9="Nữ",YEAR(TODAY())-C9>55),"Quá tuổi theo học","Đảm bảo")))) | O9: =IF(B9="","",IF(OR(LEFT(B9,1)="Y",LEFT(B9,1)="A"),"",IF(I9<>"Đối tượng lao động nông thôn khác","Cần hồ sơ chứng minh nhóm đối tượng",""))) | P9: x | Q9: =IF(B9<>"",AND(D9="Nữ",I9="Người dân tộc thiểu số"),"") | R9: =IF(B9<>"",I9="Người dân tộc thiểu số","") | S9: =IF(B9<>"",MENU!$E$5-'Thông tin hoc sinh'!C9<31,"") | T9: =IF(B9<>"",AND(R9,S9),"") | U9: =IF(B9<>"",(H9>=9),"") | V9: =IF(B9<>"",AND(U9,D9="Nữ"),"") | W9: =IF(B9<>"",AND(U9,R9),"") | X9: =IF(B9<>"",MENU!$E$5-'Thông tin hoc sinh'!C9<26,"") | Y9: =IF(B9<>"",AND(X9,D9="Nữ"),"") | Z9: =IF(B9<>"",AND(X9,R9),"") | AA9: =IF(B9<>"",AND(MENU!$E$5-'Thông tin hoc sinh'!C9>=26,MENU!$E$5-'Thông tin hoc sinh'!C9<=45),"") | AB9: =IF(B9<>"",AND(AA9,D9="Nữ"),"") | AC9: =IF(B9<>"",AND(AA9,R9),"") | AD9: =IF(B9<>"",MENU!$E$5-'Thông tin hoc sinh'!C9>45,"") | AE9: =IF(B9<>"",AND(AD9,D9="Nữ"),"") | AF9: =IF(B9<>"",AND(AD9,R9),"") | AG9: =IF(P9<>"",J9,"") | AH9: =IF(B9<>"",AND(P9="x",D9="Nữ"),"") | AI9: =IF(B9<>"",AND(P9="x",D9="Nữ",I9="Người dân tộc thiểu số"),"") | AJ9: =IF(B9<>"",AND(P9="x",I9="Người dân tộc thiểu số"),"") | AK9: =IF(B9<>"",AND(P9="x",MENU!$E$5-'Thông tin hoc sinh'!C9<31),"") | AL9: =IF(B9<>"",AND(P9="x",R9,S9),"") | AM9: =IF(B9<>"",AND(H9>=9,P9="x"),"") | AN9: =IF(B9<>"",AND(P9="x",X9,D9="Nữ"),"") | AO9: =IF(B9<>"",AND(P9="x",U9,R9),"") | AP9: =IF(B9<>"",AND(P9="x",MENU!$E$5-'Thông tin hoc sinh'!C9<26),"") | AQ9: =IF(B9<>"",AND(P9="x",X9,D9="Nữ"),"") | AR9: =IF(B9<>"",AND(P9="x",X9,R9),"") | AS9: =IF(B9<>"",AND(P9="x",MENU!$E$5-'Thông tin hoc sinh'!C9>=26,MENU!$E$5-'Thông tin hoc sinh'!C9<=45),"") | AT9: =IF(B9<>"",AND(P9="x",AA9,D9="Nữ"),"") | AU9: =IF(B9<>"",AND(P9="x",AA9,R9),"") | AV9: =IF(B9<>"",AND(P9="x",MENU!$E$5-'Thông tin hoc sinh'!C9>45),"") | AW9: =IF(B9<>"",AND(P9="x",AD9,D9="Nữ"),"") | AX9: =IF(B9<>"",AND(P9="x",AD9,R9),"")
A10: 08 | B10: Y Hen | C10: 1992 | D10: Nữ | E10: Xê Đăng | F10: =IF(YEAR(TODAY())-C10<=30,"X","") | G10: =IF(AND(F10="X",E10<>"Kinh"),"X","") | H10: 9 | I10: Người dân tộc thiểu số | J10: =VLOOKUP(I10,IDs!$B$37:$C$46,2,0) | K10: Kon Đào, ĐăkTô, Kon Tum | L10: Đăk Tô, Kon Tum | M10: Đăk Nu, Ngọk Tụ, Đăk Tô, Kon Tum | N10: =IF(C10="","",IF(YEAR(TODAY())-C10<15,"Không đủ tuổi theo học",IF(AND(D10="Nam",YEAR(TODAY())-C10>60),"Quá tuổi theo học",IF(AND(D10="Nữ",YEAR(TODAY())-C10>55),"Quá tuổi theo học","Đảm bảo")))) | O10: =IF(B10="","",IF(OR(LEFT(B10,1)="Y",LEFT(B10,1)="A"),"",IF(I10<>"Đối tượng lao động nông thôn khác","Cần hồ sơ chứng minh nhóm đối tượng",""))) | P10: x | Q10: =IF(B10<>"",AND(D10="Nữ",I10="Người dân tộc thiểu số"),"") | R10: =IF(B10<>"",I10="Người dân tộc thiểu số","") | S10: =IF(B10<>"",MENU!$E$5-'Thông tin hoc sinh'!C10<31,"") | T10: =IF(B10<>"",AND(R10,S10),"") | U10: =IF(B10<>"",(H10>=9),"") | V10: =IF(B10<>"",AND(U10,D10="Nữ"),"") | W10: =IF(B10<>"",AND(U10,R10),"") | X10: =IF(B10<>"",MENU!$E$5-'Thông tin hoc sinh'!C10<26,"") | Y10: =IF(B10<>"",AND(X10,D10="Nữ"),"") | Z10: =IF(B10<>"",AND(X10,R10),"") | AA10: =IF(B10<>"",AND(MENU!$E$5-'Thông tin hoc sinh'!C10>=26,MENU!$E$5-'Thông tin hoc sinh'!C10<=45),"") | AB10: =IF(B10<>"",AND(AA10,D10="Nữ"),"") | AC10: =IF(B10<>"",AND(AA10,R10),"") | AD10: =IF(B10<>"",MENU!$E$5-'Thông tin hoc sinh'!C10>45,"") | AE10: =IF(B10<>"",AND(AD10,D10="Nữ"),"") | AF10: =IF(B10<>"",AND(AD10,R10),"") | AG10: =IF(P10<>"",J10,"") | AH10: =IF(B10<>"",AND(P10="x",D10="Nữ"),"") | AI10: =IF(B10<>"",AND(P10="x",D10="Nữ",I10="Người dân tộc thiểu số"),"") | AJ10: =IF(B10<>"",AND(P10="x",I10="Người dân tộc thiểu số"),"") | AK10: =IF(B10<>"",AND(P10="x",MENU!$E$5-'Thông tin hoc sinh'!C10<31),"") | AL10: =IF(B10<>"",AND(P10="x",R10,S10),"") | AM10: =IF(B10<>"",AND(H10>=9,P10="x"),"") | AN10: =IF(B10<>"",AND(P10="x",X10,D10="Nữ"),"") | AO10: =IF(B10<>"",AND(P10="x",U10,R10),"") | AP10: =IF(B10<>"",AND(P10="x",MENU!$E$5-'Thông tin hoc sinh'!C10<26),"") | AQ10: =IF(B10<>"",AND(P10="x",X10,D10="Nữ"),"") | AR10: =IF(B10<>"",AND(P10="x",X10,R10),"") | AS10: =IF(B10<>"",AND(P10="x",MENU!$E$5-'Thông tin hoc sinh'!C10>=26,MENU!$E$5-'Thông tin hoc sinh'!C10<=45),"") | AT10: =IF(B10<>"",AND(P10="x",AA10,D10="Nữ"),"") | AU10: =IF(B10<>"",AND(P10="x",AA10,R10),"") | AV10: =IF(B10<>"",AND(P10="x",MENU!$E$5-'Thông tin hoc sinh'!C10>45),"") | AW10: =IF(B10<>"",AND(P10="x",AD10,D10="Nữ"),"") | AX10: =IF(B10<>"",AND(P10="x",AD10,R10),"")
A11: 09 | B11: Y Dang | C11: 1998 | D11: Nữ | E11: Xê Đăng | F11: =IF(YEAR(TODAY())-C11<=30,"X","") | G11: =IF(AND(F11="X",E11<>"Kinh"),"X","") | H11: 10 | I11: Người dân tộc thiểu số | J11: =VLOOKUP(I11,IDs!$B$37:$C$46,2,0) | K11: Kon Đào, ĐăkTô, Kon Tum | L11: Đăk Tô, Kon Tum | M11: Đăk Nu, Ngọk Tụ, Đăk Tô, Kon Tum | N11: =IF(C11="","",IF(YEAR(TODAY())-C11<15,"Không đủ tuổi theo học",IF(AND(D11="Nam",YEAR(TODAY())-C11>60),"Quá tuổi theo học",IF(AND(D11="Nữ",YEAR(TODAY())-C11>55),"Quá tuổi theo học","Đảm bảo")))) | O11: =IF(B11="","",IF(OR(LEFT(B11,1)="Y",LEFT(B11,1)="A"),"",IF(I11<>"Đối tượng lao động nông thôn khác","Cần hồ sơ chứng minh nhóm đối tượng",""))) | P11: x | Q11: =IF(B11<>"",AND(D11="Nữ",I11="Người dân tộc thiểu số"),"") | R11: =IF(B11<>"",I11="Người dân tộc thiểu số","") | S11: =IF(B11<>"",MENU!$E$5-'Thông tin hoc sinh'!C11<31,"") | T11: =IF(B11<>"",AND(R11,S11),"") | U11: =IF(B11<>"",(H11>=9),"") | V11: =IF(B11<>"",AND(U11,D11="Nữ"),"") | W11: =IF(B11<>"",AND(U11,R11),"") | X11: =IF(B11<>"",MENU!$E$5-'Thông tin hoc sinh'!C11<26,"") | Y11: =IF(B11<>"",AND(X11,D11="Nữ"),"") | Z11: =IF(B11<>"",AND(X11,R11),"") | AA11: =IF(B11<>"",AND(MENU!$E$5-'Thông tin hoc sinh'!C11>=26,MENU!$E$5-'Thông tin hoc sinh'!C11<=45),"") | AB11: =IF(B11<>"",AND(AA11,D11="Nữ"),"") | AC11: =IF(B11<>"",AND(AA11,R11),"") | AD11: =IF(B11<>"",MENU!$E$5-'Thông tin hoc sinh'!C11>45,"") | AE11: =IF(B11<>"",AND(AD11,D11="Nữ"),"") | AF11: =IF(B11<>"",AND(AD11,R11),"") | AG11: =IF(P11<>"",J11,"") | AH11: =IF(B11<>"",AND(P11="x",D11="Nữ"),"") | AI11: =IF(B11<>"",AND(P11="x",D11="Nữ",I11="Người dân tộc thiểu số"),"") | AJ11: =IF(B11<>"",AND(P11="x",I11="Người dân tộc thiểu số"),"") | AK11: =IF(B11<>"",AND(P11="x",MENU!$E$5-'Thông tin hoc sinh'!C11<31),"") | AL11: =IF(B11<>"",AND(P11="x",R11,S11),"") | AM11: =IF(B11<>"",AND(H11>=9,P11="x"),"") | AN11: =IF(B11<>"",AND(P11="x",X11,D11="Nữ"),"") | AO11: =IF(B11<>"",AND(P11="x",U11,R11),"") | AP11: =IF(B11<>"",AND(P11="x",MENU!$E$5-'Thông tin hoc sinh'!C11<26),"") | AQ11: =IF(B11<>"",AND(P11="x",X11,D11="Nữ"),"") | AR11: =IF(B11<>"",AND(P11="x",X11,R11),"") | AS11: =IF(B11<>"",AND(P11="x",MENU!$E$5-'Thông tin hoc sinh'!C11>=26,MENU!$E$5-'Thông tin hoc sinh'!C11<=45),"") | AT11: =IF(B11<>"",AND(P11="x",AA11,D11="Nữ"),"") | AU11: =IF(B11<>"",AND(P11="x",AA11,R11),"") | AV11: =IF(B11<>"",AND(P11="x",MENU!$E$5-'Thông tin hoc sinh'!C11>45),"") | AW11: =IF(B11<>"",AND(P11="x",AD11,D11="Nữ"),"") | AX11: =IF(B11<>"",AND(P11="x",AD11,R11),"")
A12: 10 | B12: Y Thoan | C12: 1998 | D12: Nữ | E12: Xê Đăng | F12: =IF(YEAR(TODAY())-C12<=30,"X","") | G12: =IF(AND(F12="X",E12<>"Kinh"),"X","") | H12: 9 | I12: Người dân tộc thiểu số | J12: =VLOOKUP(I12,IDs!$B$37:$C$46,2,0) | K12: Kon Đào, ĐăkTô, Kon Tum | L12: Đăk Tô, Kon Tum | M12: Đăk Nu, Ngọk Tụ, Đăk Tô, Kon Tum | N12: =IF(C12="","",IF(YEAR(TODAY())-C12<15,"Không đủ tuổi theo học",IF(AND(D12="Nam",YEAR(TODAY())-C12>60),"Quá tuổi theo học",IF(AND(D12="Nữ",YEAR(TODAY())-C12>55),"Quá tuổi theo học","Đảm bảo")))) | O12: =IF(B12="","",IF(OR(LEFT(B12,1)="Y",LEFT(B12,1)="A"),"",IF(I12<>"Đối tượng lao động nông thôn khác","Cần hồ sơ chứng minh nhóm đối tượng",""))) | P12: x | Q12: =IF(B12<>"",AND(D12="Nữ",I12="Người dân tộc thiểu số"),"") | R12: =IF(B12<>"",I12="Người dân tộc thiểu số","") | S12: =IF(B12<>"",MENU!$E$5-'Thông tin hoc sinh'!C12<31,"") | T12: =IF(B12<>"",AND(R12,S12),"") | U12: =IF(B12<>"",(H12>=9),"") | V12: =IF(B12<>"",AND(U12,D12="Nữ"),"") | W12: =IF(B12<>"",AND(U12,R12),"") | X12: =IF(B12<>"",MENU!$E$5-'Thông tin hoc sinh'!C12<26,"") | Y12: =IF(B12<>"",AND(X12,D12="Nữ"),"") | Z12: =IF(B12<>"",AND(X12,R12),"") | AA12: =IF(B12<>"",AND(MENU!$E$5-'Thông tin hoc sinh'!C12>=26,MENU!$E$5-'Thông tin hoc sinh'!C12<=45),"") | AB12: =IF(B12<>"",AND(AA12,D12="Nữ"),"") | AC12: =IF(B12<>"",AND(AA12,R12),"") | AD12: =IF(B12<>"",MENU!$E$5-'Thông tin hoc sinh'!C12>45,"") | AE12: =IF(B12<>"",AND(AD12,D12="Nữ"),"") | AF12: =IF(B12<>"",AND(AD12,R12),"") | AG12: =IF(P12<>"",J12,"") | AH12: =IF(B12<>"",AND(P12="x",D12="Nữ"),"") | AI12: =IF(B12<>"",AND(P12="x",D12="Nữ",I12="Người dân tộc thiểu số"),"") | AJ12: =IF(B12<>"",AND(P12="x",I12="Người dân tộc thiểu số"),"") | AK12: =IF(B12<>"",AND(P12="x",MENU!$E$5-'Thông tin hoc sinh'!C12<31),"") | AL12: =IF(B12<>"",AND(P12="x",R12,S12),"") | AM12: =IF(B12<>"",AND(H12>=9,P12="x"),"") | AN12: =IF(B12<>"",AND(P12="x",X12,D12="Nữ"),"") | AO12: =IF(B12<>"",AND(P12="x",U12,R12),"") | AP12: =IF(B12<>"",AND(P12="x",MENU!$E$5-'Thông tin hoc sinh'!C12<26),"") | AQ12: =IF(B12<>"",AND(P12="x",X12,D12="Nữ"),"") | AR12: =IF(B12<>"",AND(P12="x",X12,R12),"") | AS12: =IF(B12<>"",AND(P12="x",MENU!$E$5-'Thông tin hoc sinh'!C12>=26,MENU!$E$5-'Thông tin hoc sinh'!C12<=45),"") | AT12: =IF(B12<>"",AND(P12="x",AA12,D12="Nữ"),"") | AU12: =IF(B12<>"",AND(P12="x",AA12,R12),"") | AV12: =IF(B12<>"",AND(P12="x",MENU!$E$5-'Thông tin hoc sinh'!C12>45),"") | AW12: =IF(B12<>"",AND(P12="x",AD12,D12="Nữ"),"") | AX12: =IF(B12<>"",AND(P12="x",AD12,R12),"")
A13: 11 | B13: Y Điệp | C13: 1988 | D13: Nữ | E13: Xê Đăng | F13: =IF(YEAR(TODAY())-C13<=30,"X","") | G13: =IF(AND(F13="X",E13<>"Kinh"),"X","") | H13: 4 | I13: Người dân tộc thiểu số | J13: =VLOOKUP(I13,IDs!$B$37:$C$46,2,0) | K13: Kon Đào, ĐăkTô, Kon Tum | L13: Đăk Tô, Kon Tum | M13: Đăk Nu, Ngọk Tụ, Đăk Tô, Kon Tum | N13: =IF(C13="","",IF(YEAR(TODAY())-C13<15,"Không đủ tuổi theo học",IF(AND(D13="Nam",YEAR(TODAY())-C13>60),"Quá tuổi theo học",IF(AND(D13="Nữ",YEAR(TODAY())-C13>55),"Quá tuổi theo học","Đảm bảo")))) | O13: =IF(B13="","",IF(OR(LEFT(B13,1)="Y",LEFT(B13,1)="A"),"",IF(I13<>"Đối tượng lao động nông thôn khác","Cần hồ sơ chứng minh nhóm đối tượng",""))) | P13: x | Q13: =IF(B13<>"",AND(D13="Nữ",I13="Người dân tộc thiểu số"),"") | R13: =IF(B13<>"",I13="Người dân tộc thiểu số","") | S13: =IF(B13<>"",MENU!$E$5-'Thông tin hoc sinh'!C13<31,"") | T13: =IF(B13<>"",AND(R13,S13),"") | U13: =IF(B13<>"",(H13>=9),"") | V13: =IF(B13<>"",AND(U13,D13="Nữ"),"") | W13: =IF(B13<>"",AND(U13,R13),"") | X13: =IF(B13<>"",MENU!$E$5-'Thông tin hoc sinh'!C13<26,"") | Y13: =IF(B13<>"",AND(X13,D13="Nữ"),"") | Z13: =IF(B13<>"",AND(X13,R13),"") | AA13: =IF(B13<>"",AND(MENU!$E$5-'Thông tin hoc sinh'!C13>=26,MENU!$E$5-'Thông tin hoc sinh'!C13<=45),"") | AB13: =IF(B13<>"",AND(AA13,D13="Nữ"),"") | AC13: =IF(B13<>"",AND(AA13,R13),"") | AD13: =IF(B13<>"",MENU!$E$5-'Thông tin hoc sinh'!C13>45,"") | AE13: =IF(B13<>"",AND(AD13,D13="Nữ"),"") | AF13: =IF(B13<>"",AND(AD13,R13),"") | AG13: =IF(P13<>"",J13,"") | AH13: =IF(B13<>"",AND(P13="x",D13="Nữ"),"") | AI13: =IF(B13<>"",AND(P13="x",D13="Nữ",I13="Người dân tộc thiểu số"),"") | AJ13: =IF(B13<>"",AND(P13="x",I13="Người dân tộc thiểu số"),"") | AK13: =IF(B13<>"",AND(P13="x",MENU!$E$5-'Thông tin hoc sinh'!C13<31),"") | AL13: =IF(B13<>"",AND(P13="x",R13,S13),"") | AM13: =IF(B13<>"",AND(H13>=9,P13="x"),"") | AN13: =IF(B13<>"",AND(P13="x",X13,D13="Nữ"),"") | AO13: =IF(B13<>"",AND(P13="x",U13,R13),"") | AP13: =IF(B13<>"",AND(P13="x",MENU!$E$5-'Thông tin hoc sinh'!C13<26),"") | AQ13: =IF(B13<>"",AND(P13="x",X13,D13="Nữ"),"") | AR13: =IF(B13<>"",AND(P13="x",X13,R13),"") | AS13: =IF(B13<>"",AND(P13="x",MENU!$E$5-'Thông tin hoc sinh'!C13>=26,MENU!$E$5-'Thông tin hoc sinh'!C13<=45),"") | AT13: =IF(B13<>"",AND(P13="x",AA13,D13="Nữ"),"") | AU13: =IF(B13<>"",AND(P13="x",AA13,R13),"") | AV13: =IF(B13<>"",AND(P13="x",MENU!$E$5-'Thông tin hoc sinh'!C13>45),"") | AW13: =IF(B13<>"",AND(P13="x",AD13,D13="Nữ"),"") | AX13: =IF(B13<>"",AND(P13="x",AD13,R13),"")
A14: 12 | B14: Y Đinh | C14: 1984 | D14: Nữ | E14: Xê Đăng | F14: =IF(YEAR(TODAY())-C14<=30,"X","") | G14: =IF(AND(F14="X",E14<>"Kinh"),"X","") | H14: 2 | I14: Người dân tộc thiểu số | J14: =VLOOKUP(I14,IDs!$B$37:$C$46,2,0) | K14: Kon Đào, ĐăkTô, Kon Tum | L14: Đăk Tô, Kon Tum | M14: Đăk Nu, Ngọk Tụ, Đăk Tô, Kon Tum | N14: =IF(C14="","",IF(YEAR(TODAY())-C14<15,"Không đủ tuổi theo học",IF(AND(D14="Nam",YEAR(TODAY())-C14>60),"Quá tuổi theo học",IF(AND(D14="Nữ",YEAR(TODAY())-C14>55),"Quá tuổi theo học","Đảm bảo")))) | O14: =IF(B14="","",IF(OR(LEFT(B14,1)="Y",LEFT(B14,1)="A"),"",IF(I14<>"Đối tượng lao động nông thôn khác","Cần hồ sơ chứng minh nhóm đối tượng",""))) | P14: x | Q14: =IF(B14<>"",AND(D14="Nữ",I14="Người dân tộc thiểu số"),"") | R14: =IF(B14<>"",I14="Người dân tộc thiểu số","") | S14: =IF(B14<>"",MENU!$E$5-'Thông tin hoc sinh'!C14<31,"") | T14: =IF(B14<>"",AND(R14,S14),"") | U14: =IF(B14<>"",(H14>=9),"") | V14: =IF(B14<>"",AND(U14,D14="Nữ"),"") | W14: =IF(B14<>"",AND(U14,R14),"") | X14: =IF(B14<>"",MENU!$E$5-'Thông tin hoc sinh'!C14<26,"") | Y14: =IF(B14<>"",AND(X14,D14="Nữ"),"") | Z14: =IF(B14<>"",AND(X14,R14),"") | AA14: =IF(B14<>"",AND(MENU!$E$5-'Thông tin hoc sinh'!C14>=26,MENU!$E$5-'Thông tin hoc sinh'!C14<=45),"") | AB14: =IF(B14<>"",AND(AA14,D14="Nữ"),"") | AC14: =IF(B14<>"",AND(AA14,R14),"") | AD14: =IF(B14<>"",MENU!$E$5-'Thông tin hoc sinh'!C14>45,"") | AE14: =IF(B14<>"",AND(AD14,D14="Nữ"),"") | AF14: =IF(B14<>"",AND(AD14,R14),"") | AG14: =IF(P14<>"",J14,"") | AH14: =IF(B14<>"",AND(P14="x",D14="Nữ"),"") | AI14: =IF(B14<>"",AND(P14="x",D14="Nữ",I14="Người dân tộc thiểu số"),"") | AJ14: =IF(B14<>"",AND(P14="x",I14="Người dân tộc thiểu số"),"") | AK14: =IF(B14<>"",AND(P14="x",MENU!$E$5-'Thông tin hoc sinh'!C14<31),"") | AL14: =IF(B14<>"",AND(P14="x",R14,S14),"") | AM14: =IF(B14<>"",AND(H14>=9,P14="x"),"") | AN14: =IF(B14<>"",AND(P14="x",X14,D14="Nữ"),"") | AO14: =IF(B14<>"",AND(P14="x",U14,R14),"") | AP14: =IF(B14<>"",AND(P14="x",MENU!$E$5-'Thông tin hoc sinh'!C14<26),"") | AQ14: =IF(B14<>"",AND(P14="x",X14,D14="Nữ"),"") | AR14: =IF(B14<>"",AND(P14="x",X14,R14),"") | AS14: =IF(B14<>"",AND(P14="x",MENU!$E$5-'Thông tin hoc sinh'!C14>=26,MENU!$E$5-'Thông tin hoc sinh'!C14<=45),"") | AT14: =IF(B14<>"",AND(P14="x",AA14,D14="Nữ"),"") | AU14: =IF(B14<>"",AND(P14="x",AA14,R14),"") | AV14: =IF(B14<>"",AND(P14="x",MENU!$E$5-'Thông tin hoc sinh'!C14>45),"") | AW14: =IF(B14<>"",AND(P14="x",AD14,D14="Nữ"),"") | AX14: =IF(B14<>"",AND(P14="x",AD14,R14),"")
... A34: 32 | B34: A Yêu | C34: 2001 | D34: Nam | E34: Xê Đăng | F34: =IF(YEAR(TODAY())-C34<=30,"X","") | G34: =IF(AND(F34="X",E34<>"Kinh"),"X","") | H34: 10 | I34: Người dân tộc thiểu số | J34: =VLOOKUP(I34,IDs!$B$37:$C$46,2,0) | K34: Kon Đào, ĐăkTô, Kon Tum | L34: Đăk Tô, Kon Tum | M34: Kon Pring, Ngọk Tụ, Đăk Tô, Kon Tum | N34: =IF(C34="","",IF(YEAR(TODAY())-C34<15,"Không đủ tuổi theo học",IF(AND(D34="Nam",YEAR(TODAY())-C34>60),"Quá tuổi theo học",IF(AND(D34="Nữ",YEAR(TODAY())-C34>55),"Quá tuổi theo học","Đảm bảo")))) | O34: =IF(B34="","",IF(OR(LEFT(B34,1)="Y",LEFT(B34,1)="A"),"",IF(I34<>"Đối tượng lao động nông thôn khác","Cần hồ sơ chứng minh nhóm đối tượng",""))) | P34: x | Q34: =IF(B34<>"",AND(D34="Nữ",I34="Người dân tộc thiểu số"),"") | R34: =IF(B34<>"",I34="Người dân tộc thiểu số","") | S34: =IF(B34<>"",MENU!$E$5-'Thông tin hoc sinh'!C34<31,"") | T34: =IF(B34<>"",AND(R34,S34),"") | U34: =IF(B34<>"",(H34>=9),"") | V34: =IF(B34<>"",AND(U34,D34="Nữ"),"") | W34: =IF(B34<>"",AND(U34,R34),"") | X34: =IF(B34<>"",MENU!$E$5-'Thông tin hoc sinh'!C34<26,"") | Y34: =IF(B34<>"",AND(X34,D34="Nữ"),"") | Z34: =IF(B34<>"",AND(X34,R34),"") | AA34: =IF(B34<>"",AND(MENU!$E$5-'Thông tin hoc sinh'!C34>=26,MENU!$E$5-'Thông tin hoc sinh'!C34<=45),"") | AB34: =IF(B34<>"",AND(AA34,D34="Nữ"),"") | AC34: =IF(B34<>"",AND(AA34,R34),"") | AD34: =IF(B34<>"",MENU!$E$5-'Thông tin hoc sinh'!C34>45,"") | AE34: =IF(B34<>"",AND(AD34,D34="Nữ"),"") | AF34: =IF(B34<>"",AND(AD34,R34),"") | AG34: =IF(P34<>"",J34,"") | AH34: =IF(B34<>"",AND(P34="x",D34="Nữ"),"") | AI34: =IF(B34<>"",AND(P34="x",D34="Nữ",I34="Người dân tộc thiểu số"),"") | AJ34: =IF(B34<>"",AND(P34="x",I34="Người dân tộc thiểu số"),"") | AK34: =IF(B34<>"",AND(P34="x",MENU!$E$5-'Thông tin hoc sinh'!C34<31),"") | AL34: =IF(B34<>"",AND(P34="x",R34,S34),"") | AM34: =IF(B34<>"",AND(H34>=9,P34="x"),"") | AN34: =IF(B34<>"",AND(P34="x",X34,D34="Nữ"),"") | AO34: =IF(B34<>"",AND(P34="x",U34,R34),"") | AP34: =IF(B34<>"",AND(P34="x",MENU!$E$5-'Thông tin hoc sinh'!C34<26),"") | AQ34: =IF(B34<>"",AND(P34="x",X34,D34="Nữ"),"") | AR34: =IF(B34<>"",AND(P34="x",X34,R34),"") | AS34: =IF(B34<>"",AND(P34="x",MENU!$E$5-'Thông tin hoc sinh'!C34>=26,MENU!$E$5-'Thông tin hoc sinh'!C34<=45),"") | AT34: =IF(B34<>"",AND(P34="x",AA34,D34="Nữ"),"") | AU34: =IF(B34<>"",AND(P34="x",AA34,R34),"") | AV34: =IF(B34<>"",AND(P34="x",MENU!$E$5-'Thông tin hoc sinh'!C34>45),"") | AW34: =IF(B34<>"",AND(P34="x",AD34,D34="Nữ"),"") | AX34: =IF(B34<>"",AND(P34="x",AD34,R34),"")
A35: 33 | F35: =IF(YEAR(TODAY())-C35<=30,"X","") | G35: =IF(AND(F35="X",E35<>"Kinh"),"X","") | J35: =VLOOKUP(I35,IDs!$B$37:$C$46,2,0) | N35: =IF(C35="","",IF(YEAR(TODAY())-C35<15,"Không đủ tuổi theo học",IF(AND(D35="Nam",YEAR(TODAY())-C35>60),"Quá tuổi theo học",IF(AND(D35="Nữ",YEAR(TODAY())-C35>55),"Quá tuổi theo học","Đảm bảo")))) | O35: =IF(B35="","",IF(OR(LEFT(B35,1)="Y",LEFT(B35,1)="A"),"",IF(I35<>"Đối tượng lao động nông thôn khác","Cần hồ sơ chứng minh nhóm đối tượng",""))) | Q35: =IF(B35<>"",AND(D35="Nữ",I35="Người dân tộc thiểu số"),"") | R35: =IF(B35<>"",I35="Người dân tộc thiểu số","") | S35: =IF(B35<>"",MENU!$E$5-'Thông tin hoc sinh'!C35<31,"") | T35: =IF(B35<>"",AND(R35,S35),"") | U35: =IF(B35<>"",(H35>=9),"") | V35: =IF(B35<>"",AND(U35,D35="Nữ"),"") | W35: =IF(B35<>"",AND(U35,R35),"") | X35: =IF(B35<>"",MENU!$E$5-'Thông tin hoc sinh'!C35<26,"") | Y35: =IF(B35<>"",AND(X35,D35="Nữ"),"") | Z35: =IF(B35<>"",AND(X35,R35),"") | AA35: =IF(B35<>"",AND(MENU!$E$5-'Thông tin hoc sinh'!C35>=26,MENU!$E$5-'Thông tin hoc sinh'!C35<=45),"") | AB35: =IF(B35<>"",AND(AA35,D35="Nữ"),"") | AC35: =IF(B35<>"",AND(AA35,R35),"") | AD35: =IF(B35<>"",MENU!$E$5-'Thông tin hoc sinh'!C35>45,"") | AE35: =IF(B35<>"",AND(AD35,D35="Nữ"),"") | AF35: =IF(B35<>"",AND(AD35,R35),"") | AG35: =IF(P35<>"",J35,"") | AH35: =IF(B35<>"",AND(P35="x",D35="Nữ"),"") | AI35: =IF(B35<>"",AND(P35="x",D35="Nữ",I35="Người dân tộc thiểu số"),"") | AJ35: =IF(B35<>"",AND(P35="x",I35="Người dân tộc thiểu số"),"") | AK35: =IF(B35<>"",AND(P35="x",MENU!$E$5-'Thông tin hoc sinh'!C35<31),"") | AL35: =IF(B35<>"",AND(P35="x",R35,S35),"") | AM35: =IF(B35<>"",AND(H35>=9,P35="x"),"") | AN35: =IF(B35<>"",AND(P35="x",X35,D35="Nữ"),"") | AO35: =IF(B35<>"",AND(P35="x",U35,R35),"") | AP35: =IF(B35<>"",AND(P35="x",MENU!$E$5-'Thông tin hoc sinh'!C35<26),"") | AQ35: =IF(B35<>"",AND(P35="x",X35,D35="Nữ"),"") | AR35: =IF(B35<>"",AND(P35="x",X35,R35),"") | AS35: =IF(B35<>"",AND(P35="x",MENU!$E$5-'Thông tin hoc sinh'!C35>=26,MENU!$E$5-'Thông tin hoc sinh'!C35<=45),"") | AT35: =IF(B35<>"",AND(P35="x",AA35,D35="Nữ"),"") | AU35: =IF(B35<>"",AND(P35="x",AA35,R35),"") | AV35: =IF(B35<>"",AND(P35="x",MENU!$E$5-'Thông tin hoc sinh'!C35>45),"") | AW35: =IF(B35<>"",AND(P35="x",AD35,D35="Nữ"),"") | AX35: =IF(B35<>"",AND(P35="x",AD35,R35),"")
A36: 34 | F36: =IF(YEAR(TODAY())-C36<=30,"X","") | G36: =IF(AND(F36="X",E36<>"Kinh"),"X","") | J36: =VLOOKUP(I36,IDs!$B$37:$C$46,2,0) | N36: =IF(C36="","",IF(YEAR(TODAY())-C36<15,"Không đủ tuổi theo học",IF(AND(D36="Nam",YEAR(TODAY())-C36>60),"Quá tuổi theo học",IF(AND(D36="Nữ",YEAR(TODAY())-C36>55),"Quá tuổi theo học","Đảm bảo")))) | O36: =IF(B36="","",IF(OR(LEFT(B36,1)="Y",LEFT(B36,1)="A"),"",IF(I36<>"Đối tượng lao động nông thôn khác","Cần hồ sơ chứng minh nhóm đối tượng",""))) | Q36: =IF(B36<>"",AND(D36="Nữ",I36="Người dân tộc thiểu số"),"") | R36: =IF(B36<>"",I36="Người dân tộc thiểu số","") | S36: =IF(B36<>"",MENU!$E$5-'Thông tin hoc sinh'!C36<31,"") | T36: =IF(B36<>"",AND(R36,S36),"") | U36: =IF(B36<>"",(H36>=9),"") | V36: =IF(B36<>"",AND(U36,D36="Nữ"),"") | W36: =IF(B36<>"",AND(U36,R36),"") | X36: =IF(B36<>"",MENU!$E$5-'Thông tin hoc sinh'!C36<26,"") | Y36: =IF(B36<>"",AND(X36,D36="Nữ"),"") | Z36: =IF(B36<>"",AND(X36,R36),"") | AA36: =IF(B36<>"",AND(MENU!$E$5-'Thông tin hoc sinh'!C36>=26,MENU!$E$5-'Thông tin hoc sinh'!C36<=45),"") | AB36: =IF(B36<>"",AND(AA36,D36="Nữ"),"") | AC36: =IF(B36<>"",AND(AA36,R36),"") | AD36: =IF(B36<>"",MENU!$E$5-'Thông tin hoc sinh'!C36>45,"") | AE36: =IF(B36<>"",AND(AD36,D36="Nữ"),"") | AF36: =IF(B36<>"",AND(AD36,R36),"") | AG36: =IF(P36<>"",J36,"") | AH36: =IF(B36<>"",AND(P36="x",D36="Nữ"),"") | AI36: =IF(B36<>"",AND(P36="x",D36="Nữ",I36="Người dân tộc thiểu số"),"") | AJ36: =IF(B36<>"",AND(P36="x",I36="Người dân tộc thiểu số"),"") | AK36: =IF(B36<>"",AND(P36="x",MENU!$E$5-'Thông tin hoc sinh'!C36<31),"") | AL36: =IF(B36<>"",AND(P36="x",R36,S36),"") | AM36: =IF(B36<>"",AND(H36>=9,P36="x"),"") | AN36: =IF(B36<>"",AND(P36="x",X36,D36="Nữ"),"") | AO36: =IF(B36<>"",AND(P36="x",U36,R36),"") | AP36: =IF(B36<>"",AND(P36="x",MENU!$E$5-'Thông tin hoc sinh'!C36<26),"") | AQ36: =IF(B36<>"",AND(P36="x",X36,D36="Nữ"),"") | AR36: =IF(B36<>"",AND(P36="x",X36,R36),"") | AS36: =IF(B36<>"",AND(P36="x",MENU!$E$5-'Thông tin hoc sinh'!C36>=26,MENU!$E$5-'Thông tin hoc sinh'!C36<=45),"") | AT36: =IF(B36<>"",AND(P36="x",AA36,D36="Nữ"),"") | AU36: =IF(B36<>"",AND(P36="x",AA36,R36),"") | AV36: =IF(B36<>"",AND(P36="x",MENU!$E$5-'Thông tin hoc sinh'!C36>45),"") | AW36: =IF(B36<>"",AND(P36="x",AD36,D36="Nữ"),"") | AX36: =IF(B36<>"",AND(P36="x",AD36,R36),"")
A37: 35 | F37: =IF(YEAR(TODAY())-C37<=30,"X","") | G37: =IF(AND(F37="X",E37<>"Kinh"),"X","") | J37: =VLOOKUP(I37,IDs!$B$37:$C$46,2,0) | N37: =IF(C37="","",IF(YEAR(TODAY())-C37<15,"Không đủ tuổi theo học",IF(AND(D37="Nam",YEAR(TODAY())-C37>60),"Quá tuổi theo học",IF(AND(D37="Nữ",YEAR(TODAY())-C37>55),"Quá tuổi theo học","Đảm bảo")))) | O37: =IF(B37="","",IF(OR(LEFT(B37,1)="Y",LEFT(B37,1)="A"),"",IF(I37<>"Đối tượng lao động nông thôn khác","Cần hồ sơ chứng minh nhóm đối tượng",""))) | Q37: =IF(B37<>"",AND(D37="Nữ",I37="Người dân tộc thiểu số"),"") | R37: =IF(B37<>"",I37="Người dân tộc thiểu số","") | S37: =IF(B37<>"",MENU!$E$5-'Thông tin hoc sinh'!C37<31,"") | T37: =IF(B37<>"",AND(R37,S37),"") | U37: =IF(B37<>"",(H37>=9),"") | V37: =IF(B37<>"",AND(U37,D37="Nữ"),"") | W37: =IF(B37<>"",AND(U37,R37),"") | X37: =IF(B37<>"",MENU!$E$5-'Thông tin hoc sinh'!C37<26,"") | Y37: =IF(B37<>"",AND(X37,D37="Nữ"),"") | Z37: =IF(B37<>"",AND(X37,R37),"") | AA37: =IF(B37<>"",AND(MENU!$E$5-'Thông tin hoc sinh'!C37>=26,MENU!$E$5-'Thông tin hoc sinh'!C37<=45),"") | AB37: =IF(B37<>"",AND(AA37,D37="Nữ"),"") | AC37: =IF(B37<>"",AND(AA37,R37),"") | AD37: =IF(B37<>"",MENU!$E$5-'Thông tin hoc sinh'!C37>45,"") | AE37: =IF(B37<>"",AND(AD37,D37="Nữ"),"") | AF37: =IF(B37<>"",AND(AD37,R37),"") | AG37: =IF(P37<>"",J37,"") | AH37: =IF(B37<>"",AND(P37="x",D37="Nữ"),"") | AI37: =IF(B37<>"",AND(P37="x",D37="Nữ",I37="Người dân tộc thiểu số"),"") | AJ37: =IF(B37<>"",AND(P37="x",I37="Người dân tộc thiểu số"),"") | AK37: =IF(B37<>"",AND(P37="x",MENU!$E$5-'Thông tin hoc sinh'!C37<31),"") | AL37: =IF(B37<>"",AND(P37="x",R37,S37),"") | AM37: =IF(B37<>"",AND(H37>=9,P37="x"),"") | AN37: =IF(B37<>"",AND(P37="x",X37,D37="Nữ"),"") | AO37: =IF(B37<>"",AND(P37="x",U37,R37),"") | AP37: =IF(B37<>"",AND(P37="x",MENU!$E$5-'Thông tin hoc sinh'!C37<26),"") | AQ37: =IF(B37<>"",AND(P37="x",X37,D37="Nữ"),"") | AR37: =IF(B37<>"",AND(P37="x",X37,R37),"") | AS37: =IF(B37<>"",AND(P37="x",MENU!$E$5-'Thông tin hoc sinh'!C37>=26,MENU!$E$5-'Thông tin hoc sinh'!C37<=45),"") | AT37: =IF(B37<>"",AND(P37="x",AA37,D37="Nữ"),"") | AU37: =IF(B37<>"",AND(P37="x",AA37,R37),"") | AV37: =IF(B37<>"",AND(P37="x",MENU!$E$5-'Thông tin hoc sinh'!C37>45),"") | AW37: =IF(B37<>"",AND(P37="x",AD37,D37="Nữ"),"") | AX37: =IF(B37<>"",AND(P37="x",AD37,R37),"")
P38: =COUNTIF(P3:P37,"TRUE") | Q38: =COUNTIF(Q3:Q37,"TRUE") | R38: =COUNTIF(R3:R37,"TRUE") | S38: =COUNTIF(S3:S37,"TRUE") | T38: =COUNTIF(T3:T37,"TRUE") | U38: =COUNTIF(U3:U37,"TRUE") | V38: =COUNTIF(V3:V37,"TRUE") | W38: =COUNTIF(W3:W37,"TRUE") | ... AF38: =COUNTIF(AF3:AF37,"TRUE") | AH38: =COUNTIF(AH3:AH37,"TRUE") | AI38: =COUNTIF(AI3:AI37,"TRUE") | AJ38: =COUNTIF(AJ3:AJ37,"TRUE") | AK38: =COUNTIF(AK3:AK37,"TRUE") | AL38: =COUNTIF(AL3:AL37,"TRUE") | AM38: =COUNTIF(AM3:AM37,"TRUE") | AN38: =COUNTIF(AN3:AN37,"TRUE") | AO38: =COUNTIF(AO3:AO37,"TRUE") | ... AX38: =COUNTIF(AX3:AX37,"TRUE")

Sheet DSTN
D1: UBND HUYỆN ĐĂK TÔ | K1: CỘNG HÒA XÃ HỘI CHỦ NGHĨA VIỆT NAM
D2: TRUNG TÂM GDNN - GDTX | K2: Độc lập - Tự do - Hạnh phúc
A5: DANH SÁCH TRÍCH NGANG HỌC VIÊN
A6: ="Đào tạo nghề cho lao động nông thôn - Nghề: "&MENU!E3&"; Khóa: "&MENU!E4&"; Năm "&MENU!E5
A7: ="Địa điểm mở lớp: xã "&MENU!E6&" - huyện "&MENU!E7&" - tỉnh Kon Tum"
A8: ="(Danh sách kèm theo Quyết định số: /QĐ-GDNN-GDTX ngày tháng năm "&MENU!E5&" của Giám đốc Trung tâm GDNN-GDTX huyện Đăk Tô)"
A9: Số TT | B9: Họ và tên | D9: Ngày, tháng, năm sinh | E9: Giới tính | F9: Dân tộc | G9: Thanh niên | H9: Thanh niên DTTS | I9: Trình độ văn hóa | J9: Nhóm đối tượng | K9: Nguyên quán | L9: Nơi cư trú | M9: Ghi chú
A10: 01 | B10: =LEFT('Thông tin hoc sinh'!B3,LEN('Thông tin hoc sinh'!B3)-LEN(C10)) | C10: =RIGHT('Thông tin hoc sinh'!B3,LEN('Thông tin hoc sinh'!B3)-FIND("*",SUBSTITUTE('Thông tin hoc sinh'!B3," ","*",LEN('Thông tin hoc sinh'!B3)-LEN(SUBSTITUTE('Thông tin hoc sinh'!B3," ",""))))) | D10: ='Thông tin hoc sinh'!C3 | E10: ='Thông tin hoc sinh'!D3 | F10: ='Thông tin hoc sinh'!E3 | G10: ='Thông tin hoc sinh'!F3 | H10: ='Thông tin hoc sinh'!G3 | I10: =IF('Thông tin hoc sinh'!H3>0,'Thông tin hoc sinh'!H3,"Không") | J10: ='Thông tin hoc sinh'!J3 | K10: ='Thông tin hoc sinh'!L3 | L10: ='Thông tin hoc sinh'!M3
A11: 02 | B11: =LEFT('Thông tin hoc sinh'!B4,LEN('Thông tin hoc sinh'!B4)-LEN(C11)) | C11: =RIGHT('Thông tin hoc sinh'!B4,LEN('Thông tin hoc sinh'!B4)-FIND("*",SUBSTITUTE('Thông tin hoc sinh'!B4," ","*",LEN('Thông tin hoc sinh'!B4)-LEN(SUBSTITUTE('Thông tin hoc sinh'!B4," ",""))))) | D11: ='Thông tin hoc sinh'!C4 | E11: ='Thông tin hoc sinh'!D4 | F11: ='Thông tin hoc sinh'!E4 | G11: ='Thông tin hoc sinh'!F4 | H11: ='Thông tin hoc sinh'!G4 | I11: =IF('Thông tin hoc sinh'!H4>0,'Thông tin hoc sinh'!H4,"Không") | J11: ='Thông tin hoc sinh'!J4 | K11: ='Thông tin hoc sinh'!L4 | L11: ='Thông tin hoc sinh'!M4
A12: 03 | B12: =LEFT('Thông tin hoc sinh'!B5,LEN('Thông tin hoc sinh'!B5)-LEN(C12)) | C12: =RIGHT('Thông tin hoc sinh'!B5,LEN('Thông tin hoc sinh'!B5)-FIND("*",SUBSTITUTE('Thông tin hoc sinh'!B5," ","*",LEN('Thông tin hoc sinh'!B5)-LEN(SUBSTITUTE('Thông tin hoc sinh'!B5," ",""))))) | D12: ='Thông tin hoc sinh'!C5 | E12: ='Thông tin hoc sinh'!D5 | F12: ='Thông tin hoc sinh'!E5 | G12: ='Thông tin hoc sinh'!F5 | H12: ='Thông tin hoc sinh'!G5 | I12: =IF('Thông tin hoc sinh'!H5>0,'Thông tin hoc sinh'!H5,"Không") | J12: ='Thông tin hoc sinh'!J5 | K12: ='Thông tin hoc sinh'!L5 | L12: ='Thông tin hoc sinh'!M5
A13: 04 | B13: =LEFT('Thông tin hoc sinh'!B6,LEN('Thông tin hoc sinh'!B6)-LEN(C13)) | C13: =RIGHT('Thông tin hoc sinh'!B6,LEN('Thông tin hoc sinh'!B6)-FIND("*",SUBSTITUTE('Thông tin hoc sinh'!B6," ","*",LEN('Thông tin hoc sinh'!B6)-LEN(SUBSTITUTE('Thông tin hoc sinh'!B6," ",""))))) | D13: ='Thông tin hoc sinh'!C6 | E13: ='Thông tin hoc sinh'!D6 | F13: ='Thông tin hoc sinh'!E6 | G13: ='Thông tin hoc sinh'!F6 | H13: ='Thông tin hoc sinh'!G6 | I13: =IF('Thông tin hoc sinh'!H6>0,'Thông tin hoc sinh'!H6,"Không") | J13: ='Thông tin hoc sinh'!J6 | K13: ='Thông tin hoc sinh'!L6 | L13: ='Thông tin hoc sinh'!M6
A14: 05 | B14: =LEFT('Thông tin hoc sinh'!B7,LEN('Thông tin hoc sinh'!B7)-LEN(C14)) | C14: =RIGHT('Thông tin hoc sinh'!B7,LEN('Thông tin hoc sinh'!B7)-FIND("*",SUBSTITUTE('Thông tin hoc sinh'!B7," ","*",LEN('Thông tin hoc sinh'!B7)-LEN(SUBSTITUTE('Thông tin hoc sinh'!B7," ",""))))) | D14: ='Thông tin hoc sinh'!C7 | E14: ='Thông tin hoc sinh'!D7 | F14: ='Thông tin hoc sinh'!E7 | G14: ='Thông tin hoc sinh'!F7 | H14: ='Thông tin hoc sinh'!G7 | I14: =IF('Thông tin hoc sinh'!H7>0,'Thông tin hoc sinh'!H7,"Không") | J14: ='Thông tin hoc sinh'!J7 | K14: ='Thông tin hoc sinh'!L7 | L14: ='Thông tin hoc sinh'!M7
A15: 06 | B15: =LEFT('Thông tin hoc sinh'!B8,LEN('Thông tin hoc sinh'!B8)-LEN(C15)) | C15: =RIGHT('Thông tin hoc sinh'!B8,LEN('Thông tin hoc sinh'!B8)-FIND("*",SUBSTITUTE('Thông tin hoc sinh'!B8," ","*",LEN('Thông tin hoc sinh'!B8)-LEN(SUBSTITUTE('Thông tin hoc sinh'!B8," ",""))))) | D15: ='Thông tin hoc sinh'!C8 | E15: ='Thông tin hoc sinh'!D8 | F15: ='Thông tin hoc sinh'!E8 | G15: ='Thông tin hoc sinh'!F8 | H15: ='Thông tin hoc sinh'!G8 | I15: =IF('Thông tin hoc sinh'!H8>0,'Thông tin hoc sinh'!H8,"Không") | J15: ='Thông tin hoc sinh'!J8 | K15: ='Thông tin hoc sinh'!L8 | L15: ='Thông tin hoc sinh'!M8
A16: 07 | B16: =LEFT('Thông tin hoc sinh'!B9,LEN('Thông tin hoc sinh'!B9)-LEN(C16)) | C16: =RIGHT('Thông tin hoc sinh'!B9,LEN('Thông tin hoc sinh'!B9)-FIND("*",SUBSTITUTE('Thông tin hoc sinh'!B9," ","*",LEN('Thông tin hoc sinh'!B9)-LEN(SUBSTITUTE('Thông tin hoc sinh'!B9," ",""))))) | D16: ='Thông tin hoc sinh'!C9 | E16: ='Thông tin hoc sinh'!D9 | F16: ='Thông tin hoc sinh'!E9 | G16: ='Thông tin hoc sinh'!F9 | H16: ='Thông tin hoc sinh'!G9 | I16: =IF('Thông tin hoc sinh'!H9>0,'Thông tin hoc sinh'!H9,"Không") | J16: ='Thông tin hoc sinh'!J9 | K16: ='Thông tin hoc sinh'!L9 | L16: ='Thông tin hoc sinh'!M9
A17: 08 | B17: =LEFT('Thông tin hoc sinh'!B10,LEN('Thông tin hoc sinh'!B10)-LEN(C17)) | C17: =RIGHT('Thông tin hoc sinh'!B10,LEN('Thông tin hoc sinh'!B10)-FIND("*",SUBSTITUTE('Thông tin hoc sinh'!B10," ","*",LEN('Thông tin hoc sinh'!B10)-LEN(SUBSTITUTE('Thông tin hoc sinh'!B10," ",""))))) | D17: ='Thông tin hoc sinh'!C10 | E17: ='Thông tin hoc sinh'!D10 | F17: ='Thông tin hoc sinh'!E10 | G17: ='Thông tin hoc sinh'!F10 | H17: ='Thông tin hoc sinh'!G10 | I17: =IF('Thông tin hoc sinh'!H10>0,'Thông tin hoc sinh'!H10,"Không") | J17: ='Thông tin hoc sinh'!J10 | K17: ='Thông tin hoc sinh'!L10 | L17: ='Thông tin hoc sinh'!M10
A18: 09 | B18: =LEFT('Thông tin hoc sinh'!B11,LEN('Thông tin hoc sinh'!B11)-LEN(C18)) | C18: =RIGHT('Thông tin hoc sinh'!B11,LEN('Thông tin hoc sinh'!B11)-FIND("*",SUBSTITUTE('Thông tin hoc sinh'!B11," ","*",LEN('Thông tin hoc sinh'!B11)-LEN(SUBSTITUTE('Thông tin hoc sinh'!B11," ",""))))) | D18: ='Thông tin hoc sinh'!C11 | E18: ='Thông tin hoc sinh'!D11 | F18: ='Thông tin hoc sinh'!E11 | G18: ='Thông tin hoc sinh'!F11 | H18: ='Thông tin hoc sinh'!G11 | I18: =IF('Thông tin hoc sinh'!H11>0,'Thông tin hoc sinh'!H11,"Không") | J18: ='Thông tin hoc sinh'!J11 | K18: ='Thông tin hoc sinh'!L11 | L18: ='Thông tin hoc sinh'!M11
A19: 10 | B19: =LEFT('Thông tin hoc sinh'!B12,LEN('Thông tin hoc sinh'!B12)-LEN(C19)) | C19: =RIGHT('Thông tin hoc sinh'!B12,LEN('Thông tin hoc sinh'!B12)-FIND("*",SUBSTITUTE('Thông tin hoc sinh'!B12," ","*",LEN('Thông tin hoc sinh'!B12)-LEN(SUBSTITUTE('Thông tin hoc sinh'!B12," ",""))))) | D19: ='Thông tin hoc sinh'!C12 | E19: ='Thông tin hoc sinh'!D12 | F19: ='Thông tin hoc sinh'!E12 | G19: ='Thông tin hoc sinh'!F12 | H19: ='Thông tin hoc sinh'!G12 | I19: =IF('Thông tin hoc sinh'!H12>0,'Thông tin hoc sinh'!H12,"Không") | J19: ='Thông tin hoc sinh'!J12 | K19: ='Thông tin hoc sinh'!L12 | L19: ='Thông tin hoc sinh'!M12
A20: 11 | B20: =LEFT('Thông tin hoc sinh'!B13,LEN('Thông tin hoc sinh'!B13)-LEN(C20)) | C20: =RIGHT('Thông tin hoc sinh'!B13,LEN('Thông tin hoc sinh'!B13)-FIND("*",SUBSTITUTE('Thông tin hoc sinh'!B13," ","*",LEN('Thông tin hoc sinh'!B13)-LEN(SUBSTITUTE('Thông tin hoc sinh'!B13," ",""))))) | D20: ='Thông tin hoc sinh'!C13 | E20: ='Thông tin hoc sinh'!D13 | F20: ='Thông tin hoc sinh'!E13 | G20: ='Thông tin hoc sinh'!F13 | H20: ='Thông tin hoc sinh'!G13 | I20: =IF('Thông tin hoc sinh'!H13>0,'Thông tin hoc sinh'!H13,"Không") | J20: ='Thông tin hoc sinh'!J13 | K20: ='Thông tin hoc sinh'!L13 | L20: ='Thông tin hoc sinh'!M13
A21: 12 | B21: =LEFT('Thông tin hoc sinh'!B14,LEN('Thông tin hoc sinh'!B14)-LEN(C21)) | C21: =RIGHT('Thông tin hoc sinh'!B14,LEN('Thông tin hoc sinh'!B14)-FIND("*",SUBSTITUTE('Thông tin hoc sinh'!B14," ","*",LEN('Thông tin hoc sinh'!B14)-LEN(SUBSTITUTE('Thông tin hoc sinh'!B14," ",""))))) | D21: ='Thông tin hoc sinh'!C14 | E21: ='Thông tin hoc sinh'!D14 | F21: ='Thông tin hoc sinh'!E14 | G21: ='Thông tin hoc sinh'!F14 | H21: ='Thông tin hoc sinh'!G14 | I21: =IF('Thông tin hoc sinh'!H14>0,'Thông tin hoc sinh'!H14,"Không") | J21: ='Thông tin hoc sinh'!J14 | K21: ='Thông tin hoc sinh'!L14 | L21: ='Thông tin hoc sinh'!M14
... A44: 35 | B44: =LEFT('Thông tin hoc sinh'!B37,LEN('Thông tin hoc sinh'!B37)-LEN(C44)) | C44: =RIGHT('Thông tin hoc sinh'!B37,LEN('Thông tin hoc sinh'!B37)-FIND("*",SUBSTITUTE('Thông tin hoc sinh'!B37," ","*",LEN('Thông tin hoc sinh'!B37)-LEN(SUBSTITUTE('Thông tin hoc sinh'!B37," ",""))))) | D44: ='Thông tin hoc sinh'!C37 | E44: ='Thông tin hoc sinh'!D37 | F44: ='Thông tin hoc sinh'!E37 | G44: ='Thông tin hoc sinh'!F37 | H44: ='Thông tin hoc sinh'!G37 | I44: =IF('Thông tin hoc sinh'!H37>0,'Thông tin hoc sinh'!H37,"Không") | J44: ='Thông tin hoc sinh'!J37 | K44: ='Thông tin hoc sinh'!L37 | L44: ='Thông tin hoc sinh'!M37
A46: ="- Tổng số: "&MENU!K4&" học viên;" | D46: Trong đó: | E46: ="+ Nam: "&MENU!K4-MENU!K10&" học viên;" | G46: ="+ Nữ: "&MENU!K10&" học viên;" | I46: ="+ DTTS: "&MENU!K11&" học viên;" | K46: ="+ Nữ DTTS: "&MENU!K12&" học viên; + Thanh niên: "&MENU!K13&" học viên; + Thanh niên DTTS: "&MENU!K14&" học viên"
A47: - Nhóm đối tượng:
B48: ="+ Nhóm đối tượng 1: "&COUNTIFS('Thông tin hoc sinh'!I3:I37,"Người khuyết tật")&" học viên, trong đó: Nữ: "&COUNTIFS('Thông tin hoc sinh'!I3:I37,"Người khuyết tật",'Thông tin hoc sinh'!D3:D37,"Nữ")&" học viên" | J48: ="+ Nhóm đối tượng 3: "&COUNTIFS('Thông tin hoc sinh'!J3:J37,3)&" học viên."
B49: ="+ Nhóm đối tượng 2: "&COUNTIFS('Thông tin hoc sinh'!J3:J37,2)&" học viên. Trong đó:" | J49: ="Người DTTS: "&COUNTIF('Thông tin hoc sinh'!I3:I37,"Người dân tộc thiểu số")&" học viên."
B50: ="Người thuộc hộ đồng bào DTTS nghèo: "&COUNTIF('Thông tin hoc sinh'!I3:I37,"Người thuộc hộ dân tộc thiểu số nghèo")&" học viên." | J50: ="Người được hưởng chính sách có công với cách mạng: "&COUNTIF('Thông tin hoc sinh'!I3:I37,"Người thuộc diện được hưởng chính sách ưu đãi người có công với cách mạng")&" học viên."
B51: ="Người thuộc hộ nghèo ở các xã, thôn ĐBKK: "&COUNTIF('Thông tin hoc sinh'!I3:I37,"Người thuộc hộ nghèo ở các xã, thôn, bản đặc biệt khó khăn")&" học viên." | J51: ="Người thuộc hộ nghèo: "&COUNTIF('Thông tin hoc sinh'!I3:I37,"Người thuộc hộ nghèo")&" học viên."
J52: ="Lao động thuộc diện thu hồi đất nông nghiệp, đất kinh doanh: "&COUNTIF('Thông tin hoc sinh'!I3:I37,"Người thuộc hộ gia đình bị thu hồi đất nông nghiệp, đất kinh doanh")&" học viên."
J53: ="Người lao động nữ bị mất việc làm: "&COUNTIF('Thông tin hoc sinh'!I3:I37,"lao động nữ bị mất việc làm")&" học viên."
B54: ="+ Nhóm đối tượng 4: "&COUNTIFS('Thông tin hoc sinh'!J3:J37,4)&" học viên." | J54: ="+ Nhóm đối tượng 5: "&COUNTIFS('Thông tin hoc sinh'!J3:J37,5)&" học viên."
K56: ="Đăk Tô, ngày ..… tháng ….. năm "&MENU!E5
B57: TỔ ĐÀO TẠO NGHỀ - HƯỚNG NGHIỆP | K57: TRUNG TÂM GDNN-GDTX HUYỆN ĐĂK TÔ
B62: ="UBND XÃ "&UPPER(MENU!E6) | K62: =IF(MENU!E8="Phi nông nghiệp","PHÒNG LAO ĐỘNG - TBXH HUYỆN ","PHÒNG NÔNG NGHIỆP VÀ PTNT HUYỆN ")&UPPER(MENU!E7)

Sheet Theo dõi ngày thực học
A1: THEO DÕI NGÀY THỰC HỌC CỦA HỌC VIÊN
A3: Số TT | B3: Họ và tên | D3: Sinh năm | E3: Nơi cư trú
F4: S | G4: C | H4: S | I4: C | J4: S | K4: C | L4: S | M4: C | N4: S | O4: C | P4: S | Q4: C | R4: S | S4: C | T4: S | U4: C | V4: S | W4: C | X4: S | Y4: C | Z4: S | AA4: C | AB4: S | AC4: C | AD4: S | AE4: C | AF4: S | AG4: C | AH4: S | AI4: C | AJ4: S | AK4: C
A5: 1 | B5: =DSTN!B10 | C5: =DSTN!C10 | D5: =DSTN!D10 | E5: =LEFT('Thông tin hoc sinh'!M3,LEN('Thông tin hoc sinh'!M3)-FIND("*",SUBSTITUTE('Thông tin hoc sinh'!M3,", ","*",LEN('Thông tin hoc sinh'!M3)-LEN(SUBSTITUTE('Thông tin hoc sinh'!M3,",","")))))
A6: 2 | B6: =DSTN!B11 | C6: =DSTN!C11 | D6: =DSTN!D11 | E6: =LEFT('Thông tin hoc sinh'!M4,LEN('Thông tin hoc sinh'!M4)-FIND("*",SUBSTITUTE('Thông tin hoc sinh'!M4,", ","*",LEN('Thông tin hoc sinh'!M4)-LEN(SUBSTITUTE('Thông tin hoc sinh'!M4,",","")))))
A7: 3 | B7: =DSTN!B12 | C7: =DSTN!C12 | D7: =DSTN!D12 | E7: =LEFT('Thông tin hoc sinh'!M5,LEN('Thông tin hoc sinh'!M5)-FIND("*",SUBSTITUTE('Thông tin hoc sinh'!M5,", ","*",LEN('Thông tin hoc sinh'!M5)-LEN(SUBSTITUTE('Thông tin hoc sinh'!M5,",","")))))
A8: 4 | B8: =DSTN!B13 | C8: =DSTN!C13 | D8: =DSTN!D13 | E8: =LEFT('Thông tin hoc sinh'!M6,LEN('Thông tin hoc sinh'!M6)-FIND("*",SUBSTITUTE('Thông tin hoc sinh'!M6,", ","*",LEN('Thông tin hoc sinh'!M6)-LEN(SUBSTITUTE('Thông tin hoc sinh'!M6,",","")))))
A9: 5 | B9: =DSTN!B14 | C9: =DSTN!C14 | D9: =DSTN!D14 | E9: =LEFT('Thông tin hoc sinh'!M7,LEN('Thông tin hoc sinh'!M7)-FIND("*",SUBSTITUTE('Thông tin hoc sinh'!M7,", ","*",LEN('Thông tin hoc sinh'!M7)-LEN(SUBSTITUTE('Thông tin hoc sinh'!M7,",","")))))
A10: 6 | B10: =DSTN!B15 | C10: =DSTN!C15 | D10: =DSTN!D15 | E10: =LEFT('Thông tin hoc sinh'!M8,LEN('Thông tin hoc sinh'!M8)-FIND("*",SUBSTITUTE('Thông tin hoc sinh'!M8,", ","*",LEN('Thông tin hoc sinh'!M8)-LEN(SUBSTITUTE('Thông tin hoc sinh'!M8,",","")))))
A11: 7 | B11: =DSTN!B16 | C11: =DSTN!C16 | D11: =DSTN!D16 | E11: =LEFT('Thông tin hoc sinh'!M9,LEN('Thông tin hoc sinh'!M9)-FIND("*",SUBSTITUTE('Thông tin hoc sinh'!M9,", ","*",LEN('Thông tin hoc sinh'!M9)-LEN(SUBSTITUTE('Thông tin hoc sinh'!M9,",","")))))
A12: 8 | B12: =DSTN!B17 | C12: =DSTN!C17 | D12: =DSTN!D17 | E12: =LEFT('Thông tin hoc sinh'!M10,LEN('Thông tin hoc sinh'!M10)-FIND("*",SUBSTITUTE('Thông tin hoc sinh'!M10,", ","*",LEN('Thông tin hoc sinh'!M10)-LEN(SUBSTITUTE('Thông tin hoc sinh'!M10,",","")))))
A13: 9 | B13: =DSTN!B18 | C13: =DSTN!C18 | D13: =DSTN!D18 | E13: =LEFT('Thông tin hoc sinh'!M11,LEN('Thông tin hoc sinh'!M11)-FIND("*",SUBSTITUTE('Thông tin hoc sinh'!M11,", ","*",LEN('Thông tin hoc sinh'!M11)-LEN(SUBSTITUTE('Thông tin hoc sinh'!M11,",","")))))
A14: 10 | B14: =DSTN!B19 | C14: =DSTN!C19 | D14: =DSTN!D19 | E14: =LEFT('Thông tin hoc sinh'!M12,LEN('Thông tin hoc sinh'!M12)-FIND("*",SUBSTITUTE('Thông tin hoc sinh'!M12,", ","*",LEN('Thông tin hoc sinh'!M12)-LEN(SUBSTITUTE('Thông tin hoc sinh'!M12,",","")))))
A15: 11 | B15: =DSTN!B20 | C15: =DSTN!C20 | D15: =DSTN!D20 | E15: =LEFT('Thông tin hoc sinh'!M13,LEN('Thông tin hoc sinh'!M13)-FIND("*",SUBSTITUTE('Thông tin hoc sinh'!M13,", ","*",LEN('Thông tin hoc sinh'!M13)-LEN(SUBSTITUTE('Thông tin hoc sinh'!M13,",","")))))
A16: 12 | B16: =DSTN!B21 | C16: =DSTN!C21 | D16: =DSTN!D21 | E16: =LEFT('Thông tin hoc sinh'!M14,LEN('Thông tin hoc sinh'!M14)-FIND("*",SUBSTITUTE('Thông tin hoc sinh'!M14,", ","*",LEN('Thông tin hoc sinh'!M14)-LEN(SUBSTITUTE('Thông tin hoc sinh'!M14,",","")))))
... A39: 35 | B39: =DSTN!B44 | C39: =DSTN!C44 | D39: =DSTN!D44 | E39: =LEFT('Thông tin hoc sinh'!M37,LEN('Thông tin hoc sinh'!M37)-FIND("*",SUBSTITUTE('Thông tin hoc sinh'!M37,", ","*",LEN('Thông tin hoc sinh'!M37)-LEN(SUBSTITUTE('Thông tin hoc sinh'!M37,",","")))))
B41: Nhận xét, đánh giá hàng ngày:

Sheet Xét KTKT Khóa học
A1: UBND HUYỆN ĐĂKTÔ | E1: CỘNG HÒA XÃ HỘI CHỦ NGHĨA VIỆT NAM
A2: TRUNG TÂM GDNN - GDTX | E2: Độc lập - Tự do - Hạnh phúc
A3: DANH SÁCH HỌC VIÊN ĐỦ ĐIỀU KIỆN DỰ KIỂM TRA KẾT THÚC KHÓA HỌC
A4: ="Lớp đào tạo nghề: "&MENU!E3&"; Khóa: "&MENU!E4&"; Năm "&MENU!E5
A6: Số TT | B6: Họ và tên | C6: Năm sinh | D6: Nơi cư trú | E6: Đủ điều kiện kiểm tra kết thúc khóa học | F6: Lý do không đủ điều kiện kiểm tra kết thúc khóa học
A7: 01 | B7: ='Thông tin hoc sinh'!B3 | C7: ='Thông tin hoc sinh'!C3 | D7: ='Thông tin hoc sinh'!M3 | E7: Đủ điều kiện | F7: =IF(E7="Đủ điều kiện","","Điền lý do!")
A8: 02 | B8: ='Thông tin hoc sinh'!B4 | C8: ='Thông tin hoc sinh'!C4 | D8: ='Thông tin hoc sinh'!M4 | E8: Đủ điều kiện | F8: =IF(E8="Đủ điều kiện","","Điền lý do!")
A9: 03 | B9: ='Thông tin hoc sinh'!B5 | C9: ='Thông tin hoc sinh'!C5 | D9: ='Thông tin hoc sinh'!M5 | E9: Đủ điều kiện | F9: =IF(E9="Đủ điều kiện","","Điền lý do!")
A10: 04 | B10: ='Thông tin hoc sinh'!B6 | C10: ='Thông tin hoc sinh'!C6 | D10: ='Thông tin hoc sinh'!M6 | E10: Đủ điều kiện | F10: =IF(E10="Đủ điều kiện","","Điền lý do!")
A11: 05 | B11: ='Thông tin hoc sinh'!B7 | C11: ='Thông tin hoc sinh'!C7 | D11: ='Thông tin hoc sinh'!M7 | E11: Đủ điều kiện | F11: =IF(E11="Đủ điều kiện","","Điền lý do!")
A12: 06 | B12: ='Thông tin hoc sinh'!B8 | C12: ='Thông tin hoc sinh'!C8 | D12: ='Thông tin hoc sinh'!M8 | E12: Không đủ điều kiện | F12: =IF(E12="Đủ điều kiện","","Điền lý do!")
A13: 07 | B13: ='Thông tin hoc sinh'!B9 | C13: ='Thông tin hoc sinh'!C9 | D13: ='Thông tin hoc sinh'!M9 | E13: Đủ điều kiện | F13: =IF(E13="Đủ điều kiện","","Điền lý do!")
A14: 08 | B14: ='Thông tin hoc sinh'!B10 | C14: ='Thông tin hoc sinh'!C10 | D14: ='Thông tin hoc sinh'!M10 | E14: Đủ điều kiện | F14: =IF(E14="Đủ điều kiện","","Điền lý do!")
